<?xml version="1.0" encoding="utf-8"?>
<!-- This URDF was automatically created by SolidWorks to URDF Exporter! Originally created by Stephen Brawner (brawner@gmail.com) 
     Commit Version: 1.6.0-1-g15f4949  Build Version: 1.6.7594.29634
     For more information, please see http://wiki.ros.org/sw_urdf_exporter -->
<robot
  name="linkerhand_L6_left">
  <link
    name="hand_base_link">
    <inertial>
      <origin
        xyz="0.00857878815855655 -0.0101812292867668 0.0904923011663288"
        rpy="0 0 0" />
      <mass
        value="0.989011744524491" />
      <inertia
        ixx="0.00457589209561874"
        ixy="0.000510023561222745"
        ixz="-8.86466668510805E-05"
        iyy="0.00351398853618454"
        iyz="-0.000321642420852552"
        izz="0.00195569823887101" />
    </inertial>
    <visual>
      <origin
        xyz="0 0 0"
        rpy="0 0 0" />
      <geometry>
        <mesh
          filename="meshes/hand_base_link.STL" />
      </geometry>
      <material
        name="">
        <color
          rgba="0.796078431372549 0.823529411764706 0.937254901960784 1" />
      </material>
    </visual>
    <collision>
      <origin
        xyz="0 0 0"
        rpy="0 0 0" />
      <geometry>
        <mesh
          filename="meshes/hand_base_link.STL" />
      </geometry>
    </collision>
  </link>
  <link
    name="thumb_metacarpals_base1">
    <inertial>
      <origin
        xyz="0.00076552424483875 0.0174785698821439 0.0644493696518092"
        rpy="0 0 0" />
      <mass
        value="0.989011744524491" />
      <inertia
        ixx="0.0045758920956187"
        ixy="0.000512806592707004"
        ixz="-7.07931001044523E-05"
        iyy="0.00353452721884731"
        iyz="-0.000266508497976059"
        izz="0.00193515955620828" />
    </inertial>
    <visual>
      <origin
        xyz="0 0 0"
        rpy="0 0 0" />
      <geometry>
        <mesh
          filename="meshes/thumb_metacarpals_base1.STL" />
      </geometry>
      <material
        name="">
        <color
          rgba="0.796078431372549 0.823529411764706 0.937254901960784 1" />
      </material>
    </visual>
    <collision>
      <origin
        xyz="0 0 0"
        rpy="0 0 0" />
      <geometry>
        <mesh
          filename="meshes/thumb_metacarpals_base1.STL" />
      </geometry>
    </collision>
  </link>
  <joint
    name="thunb_cmc_roll"
    type="revolute">
    <origin
      xyz="0.0078133 -0.029898 0.026692"
      rpy="-0.034907 0 0" />
    <parent
      link="hand_base_link" />
    <child
      link="thumb_metacarpals_base1" />
    <axis
      xyz="0 0 1" />
    <limit
      lower="0"
      upper="1.39"
      effort="0"
      velocity="0" />
  </joint>
  <link
    name="thumb_metacarpals">
    <inertial>
      <origin
        xyz="0.0105826201020131 0.0636768801273703 -0.00944561309614292"
        rpy="0 0 0" />
      <mass
        value="0.989011744524491" />
      <inertia
        ixx="0.00471517411049162"
        ixy="-0.000296387131279023"
        ixz="0.000234822292747517"
        iyy="0.00196737688412619"
        iyz="-0.000278534427392877"
        izz="0.00336302787605648" />
    </inertial>
    <visual>
      <origin
        xyz="0 0 0"
        rpy="0 0 0" />
      <geometry>
        <mesh
          filename="meshes/thumb_metacarpals.STL" />
      </geometry>
      <material
        name="">
        <color
          rgba="0.796078431372549 0.823529411764706 0.937254901960784 1" />
      </material>
    </visual>
    <collision>
      <origin
        xyz="0 0 0"
        rpy="0 0 0" />
      <geometry>
        <mesh
          filename="meshes/thumb_metacarpals.STL" />
      </geometry>
    </collision>
  </link>
  <joint
    name="thumb_cmc_pitch"
    type="revolute">
    <origin
      xyz="0.008374 -0.011838 0.0066685"
      rpy="1.2615 0 0.61087" />
    <parent
      link="thumb_metacarpals_base1" />
    <child
      link="thumb_metacarpals" />
    <axis
      xyz="-1 0 0" />
    <limit
      lower="0"
      upper="0.99"
      effort="0"
      velocity="0" />
  </joint>
  <link
    name="thumb_distal">
    <inertial>
      <origin
        xyz="0.0105826201018901 0.0237773829969933 -0.106021446867538"
        rpy="0 0 0" />
      <mass
        value="0.989011744524491" />
      <inertia
        ixx="0.00471517411049405"
        ixy="-0.000201791772738875"
        ixz="0.000319791996788793"
        iyy="0.00194651170522825"
        iyz="0.000219147356651716"
        izz="0.00338389305495199" />
    </inertial>
    <visual>
      <origin
        xyz="0 0 0"
        rpy="0 0 0" />
      <geometry>
        <mesh
          filename="meshes/thumb_distal.STL" />
      </geometry>
      <material
        name="">
        <color
          rgba="0.796078431372549 0.823529411764706 0.937254901960784 1" />
      </material>
    </visual>
    <collision>
      <origin
        xyz="0 0 0"
        rpy="0 0 0" />
      <geometry>
        <mesh
          filename="meshes/thumb_distal.STL" />
      </geometry>
    </collision>
  </link>
  <joint
    name="thumb_dip"
    type="revolute">
    <origin
      xyz="0 0.0061 0.0827"
      rpy="0.33787 0 0" />
    <parent
      link="thumb_metacarpals" />
    <child
      link="thumb_distal" />
    <axis
      xyz="-1 0 0" />
    <limit
      lower="0"
      upper="1.22"
      effort="0"
      velocity="0" />
    <mimic
      joint="thumb_cmc_pitch"
      multiplier="2.22"
      offset="0" />
  </joint>
  <link
    name="index_proximal">
    <inertial>
      <origin
        xyz="0.0092469997976674 0.0170279294679396 -0.0314863720817707"
        rpy="0 0 0" />
      <mass
        value="0.989011744524491" />
      <inertia
        ixx="0.00457589209565323"
        ixy="0.000504685183543645"
        ixz="-0.000115217750468202"
        iyy="0.00347609950952756"
        iyz="-0.000401323275067273"
        izz="0.00199358726549349" />
    </inertial>
    <visual>
      <origin
        xyz="0 0 0"
        rpy="0 0 0" />
      <geometry>
        <mesh
          filename="meshes/index_proximal.STL" />
      </geometry>
      <material
        name="">
        <color
          rgba="0.796078431372549 0.823529411764706 0.937254901960784 1" />
      </material>
    </visual>
    <collision>
      <origin
        xyz="0 0 0"
        rpy="0 0 0" />
      <geometry>
        <mesh
          filename="meshes/index_proximal.STL" />
      </geometry>
    </collision>
  </link>
  <joint
    name="index_mcp_pitch"
    type="revolute">
    <origin
      xyz="-0.00066821 -0.028834 0.12104"
      rpy="0.05236 0 0" />
    <parent
      link="hand_base_link" />
    <child
      link="index_proximal" />
    <axis
      xyz="0 1 0" />
    <limit
      lower="0"
      upper="1.26"
      effort="0"
      velocity="0" />
  </joint>
  <link
    name="index_distal">
    <inertial>
      <origin
        xyz="0.00830951447472077 0.0170279294682548 -0.0594885348780782"
        rpy="0 0 0" />
      <mass
        value="0.989011744524491" />
      <inertia
        ixx="0.00457589209561839"
        ixy="0.000504685183580248"
        ixz="-0.00011521775045991"
        iyy="0.00347609950956193"
        iyz="-0.000401323275072238"
        izz="0.00199358726549397" />
    </inertial>
    <visual>
      <origin
        xyz="0 0 0"
        rpy="0 0 0" />
      <geometry>
        <mesh
          filename="meshes/index_distal.STL" />
      </geometry>
      <material
        name="">
        <color
          rgba="0.796078431372549 0.823529411764706 0.937254901960784 1" />
      </material>
    </visual>
    <collision>
      <origin
        xyz="0 0 0"
        rpy="0 0 0" />
      <geometry>
        <mesh
          filename="meshes/index_distal.STL" />
      </geometry>
    </collision>
  </link>
  <joint
    name="index_dip"
    type="revolute">
    <origin
      xyz="0.00093749 0 0.028002"
      rpy="0 0 0" />
    <parent
      link="index_proximal" />
    <child
      link="index_distal" />
    <axis
      xyz="0 1 0" />
    <limit
      lower="0"
      upper="1.14"
      effort="0"
      velocity="0" />
    <mimic
      joint="index_mcp_pitch"
      multiplier="1.9"
      offset="0" />
  </joint>
  <link
    name="middle_proximal">
    <inertial>
      <origin
        xyz="0.00924699979718706 -0.00141333465863674 -0.036549423957742"
        rpy="0 0 0" />
      <mass
        value="0.989011744524491" />
      <inertia
        ixx="0.00457589209561839"
        ixy="0.000510023561222953"
        ixz="-8.86466668517638E-05"
        iyy="0.00351398853618483"
        iyz="-0.000321642420852728"
        izz="0.00195569823887106" />
    </inertial>
    <visual>
      <origin
        xyz="0 0 0"
        rpy="0 0 0" />
      <geometry>
        <mesh
          filename="meshes/middle_proximal.STL" />
      </geometry>
      <material
        name="">
        <color
          rgba="0.796078431372549 0.823529411764706 0.937254901960784 1" />
      </material>
    </visual>
    <collision>
      <origin
        xyz="0 0 0"
        rpy="0 0 0" />
      <geometry>
        <mesh
          filename="meshes/middle_proximal.STL" />
      </geometry>
    </collision>
  </link>
  <joint
    name="middle_mcp_pitch"
    type="revolute">
    <origin
      xyz="-0.00066821 -0.0087679 0.12704"
      rpy="0 0 0" />
    <parent
      link="hand_base_link" />
    <child
      link="middle_proximal" />
    <axis
      xyz="0 1 0" />
    <limit
      lower="0"
      upper="1.26"
      effort="0"
      velocity="0" />
  </joint>
  <link
    name="middle_distal">
    <inertial>
      <origin
        xyz="0.00830951447493133 -0.00141333465863702 -0.0645515867540457"
        rpy="0 0 0" />
      <mass
        value="0.989011744524491" />
      <inertia
        ixx="0.00457589209561839"
        ixy="0.000510023561222953"
        ixz="-8.86466668517638E-05"
        iyy="0.00351398853618483"
        iyz="-0.000321642420852728"
        izz="0.00195569823887106" />
    </inertial>
    <visual>
      <origin
        xyz="0 0 0"
        rpy="0 0 0" />
      <geometry>
        <mesh
          filename="meshes/middle_distal.STL" />
      </geometry>
      <material
        name="">
        <color
          rgba="0.796078431372549 0.823529411764706 0.937254901960784 1" />
      </material>
    </visual>
    <collision>
      <origin
        xyz="0 0 0"
        rpy="0 0 0" />
      <geometry>
        <mesh
          filename="meshes/middle_distal.STL" />
      </geometry>
    </collision>
  </link>
  <joint
    name="middle_dip"
    type="revolute">
    <origin
      xyz="0.00093749 0 0.028002"
      rpy="0 0 0" />
    <parent
      link="middle_proximal" />
    <child
      link="middle_distal" />
    <axis
      xyz="0 1 0" />
    <limit
      lower="0"
      upper="1.14"
      effort="0"
      velocity="0" />
    <mimic
      joint="middle_mcp_pitch"
      multiplier="1.9"
      offset="0" />
  </joint>
  <link
    name="ring_proximal">
    <inertial>
      <origin
        xyz="0.00925247128768376 -0.0193514101658236 -0.0326087565608211"
        rpy="0 0 0" />
      <mass
        value="0.989011744524491" />
      <inertia
        ixx="0.00457589209561839"
        ixy="0.000513963999735352"
        ixz="-6.18326088929615E-05"
        iyy="0.00354334108551035"
        iyz="-0.000238437584966611"
        izz="0.00192634568954554" />
    </inertial>
    <visual>
      <origin
        xyz="0 0 0"
        rpy="0 0 0" />
      <geometry>
        <mesh
          filename="meshes/ring_proximal.STL" />
      </geometry>
      <material
        name="">
        <color
          rgba="0.796078431372549 0.823529411764706 0.937254901960784 1" />
      </material>
    </visual>
    <collision>
      <origin
        xyz="0 0 0"
        rpy="0 0 0" />
      <geometry>
        <mesh
          filename="meshes/ring_proximal.STL" />
      </geometry>
    </collision>
  </link>
  <joint
    name="ring_mcp_pitch"
    type="revolute">
    <origin
      xyz="-0.00067368 0.01085 0.12204"
      rpy="-0.05236 0 0" />
    <parent
      link="hand_base_link" />
    <child
      link="ring_proximal" />
    <axis
      xyz="0 1 0" />
    <limit
      lower="0"
      upper="1.26"
      effort="0"
      velocity="0" />
  </joint>
  <link
    name="ring_distal">
    <inertial>
      <origin
        xyz="0.00831523905181249 -0.0193514101658595 -0.0606109278290774"
        rpy="0 0 0" />
      <mass
        value="0.989011744524491" />
      <inertia
        ixx="0.00457589209561839"
        ixy="0.000513963999735352"
        ixz="-6.18326088929607E-05"
        iyy="0.00354334108551035"
        iyz="-0.000238437584966608"
        izz="0.00192634568954554" />
    </inertial>
    <visual>
      <origin
        xyz="0 0 0"
        rpy="0 0 0" />
      <geometry>
        <mesh
          filename="meshes/ring_distal.STL" />
      </geometry>
      <material
        name="">
        <color
          rgba="0.796078431372549 0.823529411764706 0.937254901960784 1" />
      </material>
    </visual>
    <collision>
      <origin
        xyz="0 0 0"
        rpy="0 0 0" />
      <geometry>
        <mesh
          filename="meshes/ring_distal.STL" />
      </geometry>
    </collision>
  </link>
  <joint
    name="ring_dip"
    type="revolute">
    <origin
      xyz="0.00093723 0 0.028002"
      rpy="0 0 0" />
    <parent
      link="ring_proximal" />
    <child
      link="ring_distal" />
    <axis
      xyz="0 1 0" />
    <limit
      lower="0"
      upper="1.14"
      effort="0"
      velocity="0" />
    <mimic
      joint="ring_mcp_pitch"
      multiplier="1.9"
      offset="0" />
  </joint>
  <link
    name="pinky_proximal">
    <inertial>
      <origin
        xyz="0.00925731055551827 -0.0375733812188533 -0.0309587906262359"
        rpy="0 0 0" />
      <mass
        value="0.989011744524491" />
      <inertia
        ixx="0.00457589209561839"
        ixy="0.000515808833683702"
        ixz="-4.38578572245639E-05"
        iyy="0.00355800419088818"
        iyz="-0.000181458814552756"
        izz="0.00191168258416771" />
    </inertial>
    <visual>
      <origin
        xyz="0 0 0"
        rpy="0 0 0" />
      <geometry>
        <mesh
          filename="meshes/pinky_proximal.STL" />
      </geometry>
      <material
        name="">
        <color
          rgba="0.796078431372549 0.823529411764706 0.937254901960784 1" />
      </material>
    </visual>
    <collision>
      <origin
        xyz="0 0 0"
        rpy="0 0 0" />
      <geometry>
        <mesh
          filename="meshes/pinky_proximal.STL" />
      </geometry>
    </collision>
  </link>
  <joint
    name="pinky_mcp_pitch"
    type="revolute">
    <origin
      xyz="-0.00067852 0.029947 0.11806"
      rpy="-0.087266 0 0" />
    <parent
      link="hand_base_link" />
    <child
      link="pinky_proximal" />
    <axis
      xyz="0 1 0" />
    <limit
      lower="0"
      upper="1.26"
      effort="0"
      velocity="0" />
  </joint>
  <link
    name="pinky_distal">
    <inertial>
      <origin
        xyz="0.00832007831962359 -0.0375733812189009 -0.0589609618944907"
        rpy="0 0 0" />
      <mass
        value="0.989011744524491" />
      <inertia
        ixx="0.00457589209561839"
        ixy="0.000515808833683702"
        ixz="-4.38578572245639E-05"
        iyy="0.00355800419088818"
        iyz="-0.000181458814552756"
        izz="0.00191168258416771" />
    </inertial>
    <visual>
      <origin
        xyz="0 0 0"
        rpy="0 0 0" />
      <geometry>
        <mesh
          filename="meshes/pinky_distal.STL" />
      </geometry>
      <material
        name="">
        <color
          rgba="0.796078431372549 0.823529411764706 0.937254901960784 1" />
      </material>
    </visual>
    <collision>
      <origin
        xyz="0 0 0"
        rpy="0 0 0" />
      <geometry>
        <mesh
          filename="meshes/pinky_distal.STL" />
      </geometry>
    </collision>
  </link>
  <joint
    name="pinky_dip"
    type="revolute">
    <origin
      xyz="0.00093723 0 0.028002"
      rpy="0 0 0" />
    <parent
      link="pinky_proximal" />
    <child
      link="pinky_distal" />
    <axis
      xyz="0 1 0" />
    <limit
      lower="0"
      upper="1.14"
      effort="0"
      velocity="0" />
    <mimic
      joint="pinky_mcp_pitch"
      multiplier="1.9"
      offset="0" />
  </joint>
</robot>