<?xml version="1.0" encoding="utf-8"?>
<!-- This URDF was automatically created by SolidWorks to URDF Exporter! Originally created by Stephen Brawner (brawner@gmail.com) 
     Commit Version: 1.6.0-1-g15f4949  Build Version: 1.6.7594.29634
     For more information, please see http://wiki.ros.org/sw_urdf_exporter -->
<robot
  name="linkerhand_l25_left.urdf">
  <link
    name="hand_base_link">
    <inertial>
      <origin
        xyz="-0.0040779 -0.00070949 0.074947"
        rpy="0 0 0" />
      <mass
        value="0.076924" />
      <inertia
        ixx="0.00019054"
        ixy="4.9103E-07"
        ixz="7.0771E-06"
        iyy="0.00015931"
        iyz="5.3085E-06"
        izz="9.9017E-05" />
    </inertial>
    <visual>
      <origin
        xyz="0 0 0"
        rpy="0 0 0" />
      <geometry>
        <mesh
          filename="meshes/hand_base_link.STL" />
      </geometry>
      <material
        name="">
        <color
          rgba="0.82353 0.82353 1 1" />
      </material>
    </visual>
    <collision>
      <origin
        xyz="0 0 0"
        rpy="0 0 0" />
      <geometry>
        <mesh
          filename="meshes/hand_base_link.STL" />
      </geometry>
    </collision>
  </link>
  <link
    name="thumb_metacarpals_base1">
    <inertial>
      <origin
        xyz="0.040785 0.0023138 -0.0021245"
        rpy="0 0 0" />
      <mass
        value="0.010336" />
      <inertia
        ixx="3.4108E-06"
        ixy="-1.7423E-07"
        ixz="-7.1009E-08"
        iyy="2.5652E-06"
        iyz="9.0488E-08"
        izz="1.8738E-06" />
    </inertial>
    <visual>
      <origin
        xyz="0 0 0"
        rpy="0 0 0" />
      <geometry>
        <mesh
          filename="meshes/thumb_metacarpals_base1.STL" />
      </geometry>
      <material
        name="">
        <color
          rgba="1 1 1 1" />
      </material>
    </visual>
    <collision>
      <origin
        xyz="0 0 0"
        rpy="0 0 0" />
      <geometry>
        <mesh
          filename="meshes/thumb_metacarpals_base1.STL" />
      </geometry>
    </collision>
  </link>
  <joint
    name="thumb_cmc_roll"
    type="revolute">
    <origin
      xyz="-0.016601 -0.0024193 0.071265"
      rpy="0 0 0" />
    <parent
      link="hand_base_link" />
    <child
      link="thumb_metacarpals_base1" />
    <axis
      xyz="-1 0 0" />
    <limit
      lower="-0.46"
      upper="0.61"
      effort="0"
      velocity="0" />
  </joint>
  <link
    name="thumb_metacarpals_base2">
    <inertial>
      <origin
        xyz="0.00015938 -0.00093721 -0.00034824"
        rpy="0 0 0" />
      <mass
        value="0.002032" />
      <inertia
        ixx="7.5522E-08"
        ixy="2.0265E-09"
        ixz="9.9762E-10"
        iyy="7.1888E-08"
        iyz="-3.6715E-09"
        izz="1.1694E-07" />
    </inertial>
    <visual>
      <origin
        xyz="0 0 0"
        rpy="0 0 0" />
      <geometry>
        <mesh
          filename="meshes/thumb_metacarpals_base2.STL" />
      </geometry>
      <material
        name="">
        <color
          rgba="0.82353 0.82353 1 1" />
      </material>
    </visual>
    <collision>
      <origin
        xyz="0 0 0"
        rpy="0 0 0" />
      <geometry>
        <mesh
          filename="meshes/thumb_metacarpals_base2.STL" />
      </geometry>
    </collision>
  </link>
  <joint
    name="thumb_cmc_yaw"
    type="revolute">
    <origin
      xyz="0.04625 -0.0083829 -4.7486E-05"
      rpy="0 0 0" />
    <parent
      link="thumb_metacarpals_base1" />
    <child
      link="thumb_metacarpals_base2" />
    <axis
      xyz="0 -0.0056645 0.99998" />
    <limit
      lower="0"
      upper="1.57"
      effort="0"
      velocity="0" />
  </joint>
  <link
    name="thumb_metacarpals">
    <inertial>
      <origin
        xyz="0.0018017 -0.016255 -0.0090252"
        rpy="0 0 0" />
      <mass
        value="0.019926" />
      <inertia
        ixx="7.9923E-06"
        ixy="-3.4387E-07"
        ixz="9.1917E-09"
        iyy="3.3833E-06"
        iyz="-1.9069E-07"
        izz="6.8835E-06" />
    </inertial>
    <visual>
      <origin
        xyz="0 0 0"
        rpy="0 0 0" />
      <geometry>
        <mesh
          filename="meshes/thumb_metacarpals.STL" />
      </geometry>
      <material
        name="">
        <color
          rgba="1 1 1 1" />
      </material>
    </visual>
    <collision>
      <origin
        xyz="0 0 0"
        rpy="0 0 0" />
      <geometry>
        <mesh
          filename="meshes/thumb_metacarpals.STL" />
      </geometry>
    </collision>
  </link>
  <joint
    name="thumb_cmc_pitch"
    type="revolute">
    <origin
      xyz="0.006883 -0.014326 0.0014313"
      rpy="0 0 0" />
    <parent
      link="thumb_metacarpals_base2" />
    <child
      link="thumb_metacarpals" />
    <axis
      xyz="-1 0 0" />
    <limit
      lower="0"
      upper="1.59"
      effort="0"
      velocity="0" />
  </joint>
  <link
    name="thumb_proximal">
    <inertial>
      <origin
        xyz="-0.00030253 -0.025916 -0.003557"
        rpy="0 0 0" />
      <mass
        value="0.0061013" />
      <inertia
        ixx="2.0127E-06"
        ixy="2.7371E-08"
        ixz="9.0509E-09"
        iyy="8.2242E-07"
        iyz="-1.1127E-07"
        izz="1.8848E-06" />
    </inertial>
    <visual>
      <origin
        xyz="0 0 0"
        rpy="0 0 0" />
      <geometry>
        <mesh
          filename="meshes/thumb_proximal.STL" />
      </geometry>
      <material
        name="">
        <color
          rgba="1 1 1 1" />
      </material>
    </visual>
    <collision>
      <origin
        xyz="0 0 0"
        rpy="0 0 0" />
      <geometry>
        <mesh
          filename="meshes/thumb_proximal.STL" />
      </geometry>
    </collision>
  </link>
  <joint
    name="thumb_mcp"
    type="revolute">
    <origin
      xyz="0 -0.034219 -0.0041406"
      rpy="0 0 0" />
    <parent
      link="thumb_metacarpals" />
    <child
      link="thumb_proximal" />
    <axis
      xyz="-1 0 0" />
    <limit
      lower="0"
      upper="1.59"
      effort="0"
      velocity="0" />
  </joint>
  <link
    name="thumb_distal">
    <inertial>
      <origin
        xyz="0.0029999 1.7135E-07 -3.0491E-08"
        rpy="0 0 0" />
      <mass
        value="4.7117E-06" />
      <inertia
        ixx="5.8882E-13"
        ixy="-3.2456E-16"
        ixz="-7.4698E-17"
        iyy="1.443E-11"
        iyz="-1.5546E-16"
        izz="1.4429E-11" />
    </inertial>
    <visual>
      <origin
        xyz="0 0 0"
        rpy="0 0 0" />
      <geometry>
        <mesh
          filename="meshes/thumb_distal.STL" />
      </geometry>
      <material
        name="">
        <color
          rgba="0.82353 0.82353 1 1" />
      </material>
    </visual>
    <collision>
      <origin
        xyz="0 0 0"
        rpy="0 0 0" />
      <geometry>
        <mesh
          filename="meshes/thumb_distal.STL" />
      </geometry>
    </collision>
  </link>
  <joint
    name="thumb_ip"
    type="revolute">
    <origin
      xyz="0 -0.046226 -0.0025751"
      rpy="0 0 0" />
    <parent
      link="thumb_proximal" />
    <child
      link="thumb_distal" />
    <axis
      xyz="-1 0 0" />
    <limit
      lower="0"
      upper="1.78"
      effort="0"
      velocity="0" />
  </joint>
  <link
    name="index_metacarpals">
    <inertial>
      <origin
        xyz="-0.001939 -5.7834E-05 0.010294"
        rpy="0 0 0" />
      <mass
        value="0.0029534" />
      <inertia
        ixx="2.0267E-07"
        ixy="-1.2811E-10"
        ixz="2.2411E-08"
        iyy="3.1656E-07"
        iyz="5.7036E-10"
        izz="2.1596E-07" />
    </inertial>
    <visual>
      <origin
        xyz="0 0 0"
        rpy="0 0 0" />
      <geometry>
        <mesh
          filename="meshes/index_metacarpals.STL" />
      </geometry>
      <material
        name="">
        <color
          rgba="1 1 1 1" />
      </material>
    </visual>
    <collision>
      <origin
        xyz="0 0 0"
        rpy="0 0 0" />
      <geometry>
        <mesh
          filename="meshes/index_metacarpals.STL" />
      </geometry>
    </collision>
  </link>
  <joint
    name="index_mcp_roll"
    type="revolute">
    <origin
      xyz="0.0014994 -0.03367 0.13471"
      rpy="0 0 0" />
    <parent
      link="hand_base_link" />
    <child
      link="index_metacarpals" />
    <axis
      xyz="1 0 0" />
    <limit
      lower="-0.24"
      upper="0.24"
      effort="0"
      velocity="0" />
  </joint>
  <link
    name="index_proximal">
    <inertial>
      <origin
        xyz="-0.0057676 -0.00013372 0.020157"
        rpy="0 0 0" />
      <mass
        value="0.0093494" />
      <inertia
        ixx="2.4628E-06"
        ixy="-1.1904E-09"
        ixz="6.3455E-08"
        iyy="2.9915E-06"
        iyz="1.4331E-08"
        izz="1.03E-06" />
    </inertial>
    <visual>
      <origin
        xyz="0 0 0"
        rpy="0 0 0" />
      <geometry>
        <mesh
          filename="meshes/index_proximal.STL" />
      </geometry>
      <material
        name="">
        <color
          rgba="1 1 1 1" />
      </material>
    </visual>
    <collision>
      <origin
        xyz="0 0 0"
        rpy="0 0 0" />
      <geometry>
        <mesh
          filename="meshes/index_proximal.STL" />
      </geometry>
    </collision>
  </link>
  <joint
    name="index_mcp_pitch"
    type="revolute">
    <origin
      xyz="0.0068598 -0.000102 0.018075"
      rpy="0 0 0" />
    <parent
      link="index_metacarpals" />
    <child
      link="index_proximal" />
    <axis
      xyz="0 0.99998 -0.0056645" />
    <limit
      lower="0"
      upper="1.68"
      effort="0"
      velocity="0" />
  </joint>
  <link
    name="index_middle">
    <inertial>
      <origin
        xyz="1.9184E-07 0.0025997 1.4761E-05"
        rpy="0 0 0" />
      <mass
        value="4.0832E-06" />
      <inertia
        ixx="9.4553E-12"
        ixy="-3.1861E-16"
        ixz="1.8887E-16"
        iyy="5.108E-13"
        iyz="-5.0639E-14"
        izz="9.4541E-12" />
    </inertial>
    <visual>
      <origin
        xyz="0 0 0"
        rpy="0 0 0" />
      <geometry>
        <mesh
          filename="meshes/index_middle.STL" />
      </geometry>
      <material
        name="">
        <color
          rgba="1 1 1 1" />
      </material>
    </visual>
    <collision>
      <origin
        xyz="0 0 0"
        rpy="0 0 0" />
      <geometry>
        <mesh
          filename="meshes/index_middle.STL" />
      </geometry>
    </collision>
  </link>
  <joint
    name="index_pip"
    type="revolute">
    <origin
      xyz="-0.0001598 -0.00024924 0.043999"
      rpy="0 0 0" />
    <parent
      link="index_proximal" />
    <child
      link="index_middle" />
    <axis
      xyz="0 0.99998 -0.0056645" />
    <limit
      lower="0"
      upper="1.27"
      effort="0"
      velocity="0" />
  </joint>
  <link
    name="index_distal">
    <inertial>
      <origin
        xyz="-7.0976E-09 0.0027238 1.6151E-07"
        rpy="0 0 0" />
      <mass
        value="9.6249E-06" />
      <inertia
        ixx="2.5159E-11"
        ixy="-1.2289E-15"
        ixz="1.0077E-15"
        iyy="2.7081E-12"
        iyz="3.8719E-15"
        izz="2.5153E-11" />
    </inertial>
    <visual>
      <origin
        xyz="0 0 0"
        rpy="0 0 0" />
      <geometry>
        <mesh
          filename="meshes/index_distal.STL" />
      </geometry>
      <material
        name="">
        <color
          rgba="1 1 1 1" />
      </material>
    </visual>
    <collision>
      <origin
        xyz="0 0 0"
        rpy="0 0 0" />
      <geometry>
        <mesh
          filename="meshes/index_distal.STL" />
      </geometry>
    </collision>
  </link>
  <joint
    name="index_dip"
    type="revolute">
    <origin
      xyz="0.00099206 -0.00025107 0.044322"
      rpy="0 0 0" />
    <parent
      link="index_middle" />
    <child
      link="index_distal" />
    <axis
      xyz="-1.5159E-05 1 0" />
    <limit
      lower="0"
      upper="1.78"
      effort="0"
      velocity="0" />
  </joint>
  <link
    name="middle_metacarpals">
    <inertial>
      <origin
        xyz="-0.001939 -5.7834E-05 0.010294"
        rpy="0 0 0" />
      <mass
        value="0.0029534" />
      <inertia
        ixx="2.0267E-07"
        ixy="-1.2811E-10"
        ixz="2.2411E-08"
        iyy="3.1656E-07"
        iyz="5.7036E-10"
        izz="2.1596E-07" />
    </inertial>
    <visual>
      <origin
        xyz="0 0 0"
        rpy="0 0 0" />
      <geometry>
        <mesh
          filename="meshes/middle_metacarpals.STL" />
      </geometry>
      <material
        name="">
        <color
          rgba="1 1 1 1" />
      </material>
    </visual>
    <collision>
      <origin
        xyz="0 0 0"
        rpy="0 0 0" />
      <geometry>
        <mesh
          filename="meshes/middle_metacarpals.STL" />
      </geometry>
    </collision>
  </link>
  <joint
    name="middle_mcp_roll"
    type="revolute">
    <origin
      xyz="0.0014992 -0.01157 0.14219"
      rpy="0 0 0" />
    <parent
      link="hand_base_link" />
    <child
      link="middle_metacarpals" />
    <axis
      xyz="1 0 0" />
    <limit
      lower="-0.24"
      upper="0.24"
      effort="0"
      velocity="0" />
  </joint>
  <link
    name="middle_proximal">
    <inertial>
      <origin
        xyz="-0.0057676 -0.00013372 0.020157"
        rpy="0 0 0" />
      <mass
        value="0.0093494" />
      <inertia
        ixx="2.4628E-06"
        ixy="-1.1904E-09"
        ixz="6.3455E-08"
        iyy="2.9915E-06"
        iyz="1.4331E-08"
        izz="1.03E-06" />
    </inertial>
    <visual>
      <origin
        xyz="0 0 0"
        rpy="0 0 0" />
      <geometry>
        <mesh
          filename="meshes/middle_proximal.STL" />
      </geometry>
      <material
        name="">
        <color
          rgba="1 1 1 1" />
      </material>
    </visual>
    <collision>
      <origin
        xyz="0 0 0"
        rpy="0 0 0" />
      <geometry>
        <mesh
          filename="meshes/middle_proximal.STL" />
      </geometry>
    </collision>
  </link>
  <joint
    name="middle_mcp_pitch"
    type="revolute">
    <origin
      xyz="0.0068598 -0.000102 0.018075"
      rpy="0 0 0" />
    <parent
      link="middle_metacarpals" />
    <child
      link="middle_proximal" />
    <axis
      xyz="0 0.99998 -0.0056645" />
    <limit
      lower="0"
      upper="1.68"
      effort="0"
      velocity="0" />
  </joint>
  <link
    name="middle_middle">
    <inertial>
      <origin
        xyz="1.9184E-07 0.0025997 1.4761E-05"
        rpy="0 0 0" />
      <mass
        value="4.0832E-06" />
      <inertia
        ixx="9.4553E-12"
        ixy="-3.1861E-16"
        ixz="1.8887E-16"
        iyy="5.108E-13"
        iyz="-5.0639E-14"
        izz="9.4541E-12" />
    </inertial>
    <visual>
      <origin
        xyz="0 0 0"
        rpy="0 0 0" />
      <geometry>
        <mesh
          filename="meshes/middle_middle.STL" />
      </geometry>
      <material
        name="">
        <color
          rgba="1 1 1 1" />
      </material>
    </visual>
    <collision>
      <origin
        xyz="0 0 0"
        rpy="0 0 0" />
      <geometry>
        <mesh
          filename="meshes/middle_middle.STL" />
      </geometry>
    </collision>
  </link>
  <joint
    name="middle_pip"
    type="revolute">
    <origin
      xyz="-0.0001598 -0.00024924 0.043999"
      rpy="0 0 0" />
    <parent
      link="middle_proximal" />
    <child
      link="middle_middle" />
    <axis
      xyz="0 0.99998 -0.0056645" />
    <limit
      lower="0"
      upper="1.27"
      effort="0"
      velocity="0" />
  </joint>
  <link
    name="middle_distal">
    <inertial>
      <origin
        xyz="-7.0976E-09 0.0027238 1.6151E-07"
        rpy="0 0 0" />
      <mass
        value="9.6249E-06" />
      <inertia
        ixx="2.5159E-11"
        ixy="-1.2289E-15"
        ixz="1.0077E-15"
        iyy="2.7081E-12"
        iyz="3.8719E-15"
        izz="2.5153E-11" />
    </inertial>
    <visual>
      <origin
        xyz="0 0 0"
        rpy="0 0 0" />
      <geometry>
        <mesh
          filename="meshes/middle_distal.STL" />
      </geometry>
      <material
        name="">
        <color
          rgba="1 1 1 1" />
      </material>
    </visual>
    <collision>
      <origin
        xyz="0 0 0"
        rpy="0 0 0" />
      <geometry>
        <mesh
          filename="meshes/middle_distal.STL" />
      </geometry>
    </collision>
  </link>
  <joint
    name="middle_dip"
    type="revolute">
    <origin
      xyz="0.00099206 -0.00025107 0.044322"
      rpy="0 0 0" />
    <parent
      link="middle_middle" />
    <child
      link="middle_distal" />
    <axis
      xyz="-1.5159E-05 1 0" />
    <limit
      lower="0"
      upper="1.78"
      effort="0"
      velocity="0" />
  </joint>
  <link
    name="ring_metacarpals">
    <inertial>
      <origin
        xyz="-0.001939 -5.7834E-05 0.010294"
        rpy="0 0 0" />
      <mass
        value="0.0029534" />
      <inertia
        ixx="2.0267E-07"
        ixy="-1.2811E-10"
        ixz="2.2411E-08"
        iyy="3.1656E-07"
        iyz="5.7036E-10"
        izz="2.1596E-07" />
    </inertial>
    <visual>
      <origin
        xyz="0 0 0"
        rpy="0 0 0" />
      <geometry>
        <mesh
          filename="meshes/ring_metacarpals.STL" />
      </geometry>
      <material
        name="">
        <color
          rgba="1 1 1 1" />
      </material>
    </visual>
    <collision>
      <origin
        xyz="0 0 0"
        rpy="0 0 0" />
      <geometry>
        <mesh
          filename="meshes/ring_metacarpals.STL" />
      </geometry>
    </collision>
  </link>
  <joint
    name="ring_mcp_roll"
    type="revolute">
    <origin
      xyz="0.0014991 0.010029 0.13469"
      rpy="0 0 0" />
    <parent
      link="hand_base_link" />
    <child
      link="ring_metacarpals" />
    <axis
      xyz="1 0 0" />
    <limit
      lower="-0.24"
      upper="0.24"
      effort="0"
      velocity="0" />
  </joint>
  <link
    name="ring_proximal">
    <inertial>
      <origin
        xyz="-0.0057676 -0.00013372 0.020157"
        rpy="0 0 0" />
      <mass
        value="0.0093494" />
      <inertia
        ixx="2.4628E-06"
        ixy="-1.1904E-09"
        ixz="6.3455E-08"
        iyy="2.9915E-06"
        iyz="1.4331E-08"
        izz="1.03E-06" />
    </inertial>
    <visual>
      <origin
        xyz="0 0 0"
        rpy="0 0 0" />
      <geometry>
        <mesh
          filename="meshes/ring_proximal.STL" />
      </geometry>
      <material
        name="">
        <color
          rgba="1 1 1 1" />
      </material>
    </visual>
    <collision>
      <origin
        xyz="0 0 0"
        rpy="0 0 0" />
      <geometry>
        <mesh
          filename="meshes/ring_proximal.STL" />
      </geometry>
    </collision>
  </link>
  <joint
    name="ring_mcp_pitch"
    type="revolute">
    <origin
      xyz="0.0068598 -0.000102 0.018075"
      rpy="0 0 0" />
    <parent
      link="ring_metacarpals" />
    <child
      link="ring_proximal" />
    <axis
      xyz="0 0.99998 -0.0056645" />
    <limit
      lower="0"
      upper="1.68"
      effort="0"
      velocity="0" />
  </joint>
  <link
    name="ring_middle">
    <inertial>
      <origin
        xyz="1.9184E-07 0.0025997 1.4761E-05"
        rpy="0 0 0" />
      <mass
        value="4.0832E-06" />
      <inertia
        ixx="9.4553E-12"
        ixy="-3.1861E-16"
        ixz="1.8887E-16"
        iyy="5.108E-13"
        iyz="-5.0639E-14"
        izz="9.4541E-12" />
    </inertial>
    <visual>
      <origin
        xyz="0 0 0"
        rpy="0 0 0" />
      <geometry>
        <mesh
          filename="meshes/ring_middle.STL" />
      </geometry>
      <material
        name="">
        <color
          rgba="1 1 1 1" />
      </material>
    </visual>
    <collision>
      <origin
        xyz="0 0 0"
        rpy="0 0 0" />
      <geometry>
        <mesh
          filename="meshes/ring_middle.STL" />
      </geometry>
    </collision>
  </link>
  <joint
    name="ring_pip"
    type="revolute">
    <origin
      xyz="-0.0001598 -0.00024924 0.043999"
      rpy="0 0 0" />
    <parent
      link="ring_proximal" />
    <child
      link="ring_middle" />
    <axis
      xyz="0 0.99998 -0.0056645" />
    <limit
      lower="0"
      upper="1.27"
      effort="0"
      velocity="0" />
  </joint>
  <link
    name="ring_distal">
    <inertial>
      <origin
        xyz="-7.0976E-09 0.0027238 1.6151E-07"
        rpy="0 0 0" />
      <mass
        value="9.6249E-06" />
      <inertia
        ixx="2.5159E-11"
        ixy="-1.2289E-15"
        ixz="1.0077E-15"
        iyy="2.7081E-12"
        iyz="3.8719E-15"
        izz="2.5153E-11" />
    </inertial>
    <visual>
      <origin
        xyz="0 0 0"
        rpy="0 0 0" />
      <geometry>
        <mesh
          filename="meshes/ring_distal.STL" />
      </geometry>
      <material
        name="">
        <color
          rgba="1 1 1 1" />
      </material>
    </visual>
    <collision>
      <origin
        xyz="0 0 0"
        rpy="0 0 0" />
      <geometry>
        <mesh
          filename="meshes/ring_distal.STL" />
      </geometry>
    </collision>
  </link>
  <joint
    name="ring_dip"
    type="revolute">
    <origin
      xyz="0.00099206 -0.00025107 0.044322"
      rpy="0 0 0" />
    <parent
      link="ring_middle" />
    <child
      link="ring_distal" />
    <axis
      xyz="-1.5159E-05 1 0" />
    <limit
      lower="0"
      upper="1.78"
      effort="0"
      velocity="0" />
  </joint>
  <link
    name="pinky_metacarpals">
    <inertial>
      <origin
        xyz="-0.001939 -5.7834E-05 0.010294"
        rpy="0 0 0" />
      <mass
        value="0.0029534" />
      <inertia
        ixx="2.0267E-07"
        ixy="-1.2811E-10"
        ixz="2.2411E-08"
        iyy="3.1656E-07"
        iyz="5.7036E-10"
        izz="2.1596E-07" />
    </inertial>
    <visual>
      <origin
        xyz="0 0 0"
        rpy="0 0 0" />
      <geometry>
        <mesh
          filename="meshes/pinky_metacarpals.STL" />
      </geometry>
      <material
        name="">
        <color
          rgba="1 1 1 1" />
      </material>
    </visual>
    <collision>
      <origin
        xyz="0 0 0"
        rpy="0 0 0" />
      <geometry>
        <mesh
          filename="meshes/pinky_metacarpals.STL" />
      </geometry>
    </collision>
  </link>
  <joint
    name="pinky_mcp_roll"
    type="revolute">
    <origin
      xyz="0.0014989 0.03213 0.11977"
      rpy="0 0 0" />
    <parent
      link="hand_base_link" />
    <child
      link="pinky_metacarpals" />
    <axis
      xyz="1 0 0" />
    <limit
      lower="-0.24"
      upper="0.24"
      effort="0"
      velocity="0" />
  </joint>
  <link
    name="pinky_proximal">
    <inertial>
      <origin
        xyz="-0.0057676 -0.00013372 0.020157"
        rpy="0 0 0" />
      <mass
        value="0.0093494" />
      <inertia
        ixx="2.4628E-06"
        ixy="-1.1904E-09"
        ixz="6.3455E-08"
        iyy="2.9915E-06"
        iyz="1.4331E-08"
        izz="1.03E-06" />
    </inertial>
    <visual>
      <origin
        xyz="0 0 0"
        rpy="0 0 0" />
      <geometry>
        <mesh
          filename="meshes/pinky_proximal.STL" />
      </geometry>
      <material
        name="">
        <color
          rgba="1 1 1 1" />
      </material>
    </visual>
    <collision>
      <origin
        xyz="0 0 0"
        rpy="0 0 0" />
      <geometry>
        <mesh
          filename="meshes/pinky_proximal.STL" />
      </geometry>
    </collision>
  </link>
  <joint
    name="pinky_mcp_pitch"
    type="revolute">
    <origin
      xyz="0.0068598 -0.000102 0.018075"
      rpy="0 0 0" />
    <parent
      link="pinky_metacarpals" />
    <child
      link="pinky_proximal" />
    <axis
      xyz="0 0.99998 -0.0056645" />
    <limit
      lower="0"
      upper="1.68"
      effort="0"
      velocity="0" />
  </joint>
  <link
    name="pinky_middle">
    <inertial>
      <origin
        xyz="1.9184E-07 0.0025997 1.4761E-05"
        rpy="0 0 0" />
      <mass
        value="4.0832E-06" />
      <inertia
        ixx="9.4553E-12"
        ixy="-3.1861E-16"
        ixz="1.8887E-16"
        iyy="5.108E-13"
        iyz="-5.0639E-14"
        izz="9.4541E-12" />
    </inertial>
    <visual>
      <origin
        xyz="0 0 0"
        rpy="0 0 0" />
      <geometry>
        <mesh
          filename="meshes/pinky_middle.STL" />
      </geometry>
      <material
        name="">
        <color
          rgba="1 1 1 1" />
      </material>
    </visual>
    <collision>
      <origin
        xyz="0 0 0"
        rpy="0 0 0" />
      <geometry>
        <mesh
          filename="meshes/pinky_middle.STL" />
      </geometry>
    </collision>
  </link>
  <joint
    name="pinky_pip"
    type="revolute">
    <origin
      xyz="-0.0001598 -0.00024924 0.043999"
      rpy="0 0 0" />
    <parent
      link="pinky_proximal" />
    <child
      link="pinky_middle" />
    <axis
      xyz="0 0.99998 -0.0056645" />
    <limit
      lower="0"
      upper="1.27"
      effort="0"
      velocity="0" />
  </joint>
  <link
    name="pinky_distal">
    <inertial>
      <origin
        xyz="-7.0976E-09 0.0027238 1.6151E-07"
        rpy="0 0 0" />
      <mass
        value="9.6249E-06" />
      <inertia
        ixx="2.5159E-11"
        ixy="-1.2289E-15"
        ixz="1.0077E-15"
        iyy="2.7081E-12"
        iyz="3.8719E-15"
        izz="2.5153E-11" />
    </inertial>
    <visual>
      <origin
        xyz="0 0 0"
        rpy="0 0 0" />
      <geometry>
        <mesh
          filename="meshes/pinky_distal.STL" />
      </geometry>
      <material
        name="">
        <color
          rgba="1 1 1 1" />
      </material>
    </visual>
    <collision>
      <origin
        xyz="0 0 0"
        rpy="0 0 0" />
      <geometry>
        <mesh
          filename="meshes/pinky_distal.STL" />
      </geometry>
    </collision>
  </link>
  <joint
    name="pinky_dip"
    type="revolute">
    <origin
      xyz="0.00099206 -0.00025107 0.044322"
      rpy="0 0 0" />
    <parent
      link="pinky_middle" />
    <child
      link="pinky_distal" />
    <axis
      xyz="-1.5159E-05 1 0" />
    <limit
      lower="0"
      upper="1.78"
      effort="0"
      velocity="0" />
  </joint>
</robot>