<?xml version="1.0" encoding="utf-8"?>
<!-- This URDF was automatically created by SolidWorks to URDF Exporter! Originally created by Stephen Brawner (brawner@gmail.com) 
     Commit Version: 1.6.0-4-g7f85cfe  Build Version: 1.6.7995.38578
     For more information, please see http://wiki.ros.org/sw_urdf_exporter -->
<robot
  name="1011">
  <link
    name="base_link">
    <inertial>
      <origin
        xyz="0.000122153727241945 0.000408198872102964 0.0349773948843507"
        rpy="0 0 0" />
      <mass
        value="0.0953275584592678" />
      <inertia
        ixx="8.12767034774874E-05"
        ixy="-1.20182058359627E-06"
        ixz="1.8603668517547E-06"
        iyy="3.66829163752885E-05"
        iyz="-5.92270024064725E-06"
        izz="5.50855700489137E-05" />
    </inertial>
    <visual>
      <origin
        xyz="0 0 0"
        rpy="0 0 0" />
      <geometry>
        <mesh
          filename="meshes/base_link.STL" />
      </geometry>
      <material
        name="">
        <color
          rgba="0.792156862745098 0.819607843137255 0.933333333333333 1" />
      </material>
    </visual>
    <collision>
      <origin
        xyz="0 0 0"
        rpy="0 0 0" />
      <geometry>
        <mesh
          filename="meshes/base_link.STL" />
      </geometry>
    </collision>
  </link>
  <link
    name="ring_metacarpals">
    <inertial>
      <origin
        xyz="0.000604992288528814 -0.000777000681643124 0.00921175861209927"
        rpy="0 0 0" />
      <mass
        value="0.00336703733173821" />
      <inertia
        ixx="2.52245609753582E-07"
        ixy="1.3957367915388E-09"
        ixz="-1.64337225544983E-08"
        iyy="2.28131148859466E-07"
        iyz="5.18441756668669E-09"
        izz="1.66457521170697E-07" />
    </inertial>
    <visual>
      <origin
        xyz="0 0 0"
        rpy="0 0 0" />
      <geometry>
        <mesh
          filename="meshes/ring_metacarpals.STL" />
      </geometry>
      <material
        name="">
        <color
          rgba="0.792156862745098 0.819607843137255 0.933333333333333 1" />
      </material>
    </visual>
    <collision>
      <origin
        xyz="0 0 0"
        rpy="0 0 0" />
      <geometry>
        <mesh
          filename="meshes/ring_metacarpals.STL" />
          
      </geometry>
    </collision>
  </link>
  <joint
    name="ring_mcp_roll"
    type="revolute">
    <origin
      xyz="0.000984164159990901 -0.0196233036484506 0.0595593160596756"
      rpy="0.000484146754163954 0.0090327772429152 0.0535483734265152" />
    <parent
      link="base_link" />
    <child
      link="ring_metacarpals" />
    <axis
      xyz="1 0 0" />
    <limit
      lower="-0.26"
      upper="0.26"
      effort="1"
      velocity="1" />
  </joint>
  <link
    name="ring_proximal">
    <inertial>
      <origin
        xyz="-0.000442405810898327 9.14959433330337E-05 0.0170991732306565"
        rpy="0 0 0" />
      <mass
        value="0.0050760533217958" />
      <inertia
        ixx="7.9802097349061E-07"
        ixy="4.96804620767589E-10"
        ixz="1.30336525851099E-08"
        iyy="7.76377361672724E-07"
        iyz="6.50584415383022E-09"
        izz="2.00454958675709E-07" />
    </inertial>
    <visual>
      <origin
        xyz="0 0 0"
        rpy="0 0 0" />
      <geometry>
        <mesh
          filename="meshes/ring_proximal.STL" />
      </geometry>
      <material
        name="">
        <color
          rgba="0.792156862745098 0.819607843137255 0.933333333333333 1" />
      </material>
    </visual>
    <collision>
      <origin
        xyz="0 0 0"
        rpy="0 0 0" />
      <geometry>
        <mesh
          filename="meshes/ring_proximal.STL" />
      </geometry>
    </collision>
  </link>
  <joint
    name="ring_mcp_pitch"
    type="revolute">
    <origin
      xyz="0.00205000000000084 -0.00142307699391602 0.0169403321062305"
      rpy="0.0838119142718017 -0.00903314306670486 -0.000758852240191828" />
    <parent
      link="ring_metacarpals" />
    <child
      link="ring_proximal" />
    <axis
      xyz="0 1 0" />
    <limit
      lower="0"
      upper="1.45"
      effort="1"
      velocity="1" />
  </joint>
  <link
    name="ring_middle">
    <inertial>
      <origin
        xyz="-3.07953615208812E-05 1.61945949635756E-05 0.012965186818066"
        rpy="0 0 0" />
      <mass
        value="0.00351914992638037" />
      <inertia
        ixx="4.05885505678015E-07"
        ixy="-1.85188429739576E-10"
        ixz="1.09283975990789E-08"
        iyy="3.87436363636499E-07"
        iyz="4.30697717728069E-10"
        izz="1.24393734331083E-07" />
    </inertial>
    <visual>
      <origin
        xyz="0 0 0"
        rpy="0 0 0" />
      <geometry>
        <mesh
          filename="meshes/ring_middle.STL" />
      </geometry>
      <material
        name="">
        <color
          rgba="0.792156862745098 0.819607843137255 0.933333333333333 1" />
      </material>
    </visual>
    <collision>
      <origin
        xyz="0 0 0"
        rpy="0 0 0" />
      <geometry>
        <mesh
          filename="meshes/ring_middle.STL" />
      </geometry>
    </collision>
  </link>
  <joint
    name="ring_pip"
    type="revolute">
    <origin
      xyz="0.000398702854897328 0 0.0374756622963914"
      rpy="0 0 0" />
    <parent
      link="ring_proximal" />
    <child
      link="ring_middle" />
    <axis
      xyz="0 1 0" />
    <limit
      lower="0"
      upper="1.45"
      effort="1"
      velocity="1" />
  </joint>
  <link
    name="ring_distal">
    <inertial>
      <origin
        xyz="-0.00162599582883669 5.76867107840787E-06 0.0106289489271671"
        rpy="0 0 0" />
      <mass
        value="0.0030085558007415" />
      <inertia
        ixx="1.60641427396609E-07"
        ixy="-4.07806615450471E-12"
        ixz="3.54886546370617E-08"
        iyy="1.52390062343029E-07"
        iyz="-6.05724354360575E-12"
        izz="7.33039277991604E-08" />
    </inertial>
    <visual>
      <origin
        xyz="0 0 0"
        rpy="0 0 0" />
      <geometry>
        <mesh
          filename="meshes/ring_distal.STL" />
      </geometry>
      <material
        name="">
        <color
          rgba="0.792156862745098 0.819607843137255 0.933333333333333 1" />
      </material>
    </visual>
    <collision>
      <origin
        xyz="0 0 0"
        rpy="0 0 0" />
      <geometry>
        <mesh
          filename="meshes/ring_distal.STL" />
      </geometry>
    </collision>
  </link>
  <joint
    name="ring_dip"
    type="revolute">
    <origin
      xyz="0.000310987014436305 0 0.0292309026345045"
      rpy="0 0 0" />
    <parent
      link="ring_middle" />
    <child
      link="ring_distal" />
    <axis
      xyz="0 1 0" />
    <limit
      lower="0"
      upper="1.45"
      effort="1"
      velocity="1" />
  </joint>
  <link
    name="pinky_metacarpals">
    <inertial>
      <origin
        xyz="0.000604992415298353 -0.00174798564812304 0.00907770691726507"
        rpy="0 0 0" />
      <mass
        value="0.00336703800549205" />
      <inertia
        ixx="2.52245635666355E-07"
        ixy="3.12791375981564E-09"
        ixz="-1.61935666749455E-08"
        iyy="2.26348062162324E-07"
        iyz="1.15615366525803E-08"
        izz="1.68240642777198E-07" />
    </inertial>
    <visual>
      <origin
        xyz="0 0 0"
        rpy="0 0 0" />
      <geometry>
        <mesh
          filename="meshes/pinky_metacarpals.STL" />
      </geometry>
      <material
        name="">
        <color
          rgba="0.792156862745098 0.819607843137255 0.933333333333333 1" />
      </material>
    </visual>
    <collision>
      <origin
        xyz="0 0 0"
        rpy="0 0 0" />
      <geometry>
        <mesh
          filename="meshes/pinky_metacarpals.STL" />
      </geometry>
    </collision>
  </link>
  <joint
    name="pinky_mcp_roll"
    type="revolute">
    <origin
      xyz="0.004476015868019 -0.0409880441556091 0.0460631677955588"
      rpy="0.00983049129128167 0.0480762501110176 0.201778667527731" />
    <parent
      link="base_link" />
    <child
      link="pinky_metacarpals" />
    <axis
      xyz="1 0 0" />
    <limit
      lower="-0.26"
      upper="0.26"
      effort="1"
      velocity="1" />
  </joint>
  <link
    name="pinky_proximal">
    <inertial>
      <origin
        xyz="0.000241573271918778 9.16621225185085E-05 0.0171032237676361"
        rpy="0 0 0" />
      <mass
        value="0.00507590942013936" />
      <inertia
        ixx="7.98071567469929E-07"
        ixy="7.55943229984881E-10"
        ixz="-1.08703328588972E-08"
        iyy="7.7633906295854E-07"
        iyz="6.48686122994881E-09"
        izz="2.00357492107178E-07" />
    </inertial>
    <visual>
      <origin
        xyz="0 0 0"
        rpy="0 0 0" />
      <geometry>
        <mesh
          filename="meshes/pinky_proximal.STL" />
      </geometry>
      <material
        name="">
        <color
          rgba="0.792156862745098 0.819607843137255 0.933333333333333 1" />
      </material>
    </visual>
    <collision>
      <origin
        xyz="0 0 0"
        rpy="0 0 0" />
      <geometry>
        <mesh
          filename="meshes/pinky_proximal.STL" />
      </geometry>
    </collision>
  </link>
  <joint
    name="pinky_mcp_pitch"
    type="revolute">
    <origin
      xyz="0.00205000000000022 -0.00320874032852877 0.0166944297747506"
      rpy="0.190111718080316 -0.0481673822387043 -0.00926527451721673" />
    <parent
      link="pinky_metacarpals" />
    <child
      link="pinky_proximal" />
    <axis
      xyz="0 1 0" />
    <limit
      lower="0"
      upper="1.45"
      effort="1"
      velocity="1" />
  </joint>
  <link
    name="pinky_middle">
    <inertial>
      <origin
        xyz="0.00048738063986078 1.61302500384305E-05 0.0129558671771622"
        rpy="0 0 0" />
      <mass
        value="0.00351935867324924" />
      <inertia
        ixx="4.06319741656534E-07"
        ixy="-1.67512786393216E-10"
        ixz="-3.51590891552475E-10"
        iyy="3.87443075843022E-07"
        iyz="4.38224443553676E-10"
        izz="1.23969900576121E-07" />
    </inertial>
    <visual>
      <origin
        xyz="0 0 0"
        rpy="0 0 0" />
      <geometry>
        <mesh
          filename="meshes/pinky_middle.STL" />
      </geometry>
      <material
        name="">
        <color
          rgba="0.792156862745098 0.819607843137255 0.933333333333333 1" />
      </material>
    </visual>
    <collision>
      <origin
        xyz="0 0 0"
        rpy="0 0 0" />
      <geometry>
        <mesh
          filename="meshes/pinky_middle.STL" />
      </geometry>
    </collision>
  </link>
  <joint
    name="pinky_pip"
    type="revolute">
    <origin
      xyz="0.00189644048380538 0 0.0374297707982703"
      rpy="0 0 0" />
    <parent
      link="pinky_proximal" />
    <child
      link="pinky_middle" />
    <axis
      xyz="0 1 0" />
    <limit
      lower="0"
      upper="1.45"
      effort="1"
      velocity="1" />
  </joint>
  <link
    name="pinky_distal">
    <inertial>
      <origin
        xyz="-0.00120007372916057 5.7912912031291E-06 0.0106856379148494"
        rpy="0 0 0" />
      <mass
        value="0.00300831401572779" />
      <inertia
        ixx="1.63335925401818E-07"
        ixy="-3.4546076099316E-12"
        ixz="3.18850321453211E-08"
        iyy="1.52389394346853E-07"
        iyz="-8.15951244770538E-12"
        izz="7.06003562963947E-08" />
    </inertial>
    <visual>
      <origin
        xyz="0 0 0"
        rpy="0 0 0" />
      <geometry>
        <mesh
          filename="meshes/pinky_distal.STL" />
      </geometry>
      <material
        name="">
        <color
          rgba="0.792156862745098 0.819607843137255 0.933333333333333 1" />
      </material>
    </visual>
    <collision>
      <origin
        xyz="0 0 0"
        rpy="0 0 0" />
      <geometry>
        <mesh
          filename="meshes/pinky_distal.STL" />
      </geometry>
    </collision>
  </link>
  <joint
    name="pinky_dip"
    type="revolute">
    <origin
      xyz="0.0014792178106367 0 0.0291951074055178"
      rpy="0 0 0" />
    <parent
      link="pinky_middle" />
    <child
      link="pinky_distal" />
    <axis
      xyz="0 1 0" />
    <limit
      lower="0"
      upper="1.45"
      effort="1"
      velocity="1" />
  </joint>
  <link
    name="middle_metacarpals">
    <inertial>
      <origin
        xyz="0.000604992200713344 -9.10133173212268E-05 0.00924402277859864"
        rpy="0 0 0" />
      <mass
        value="0.00336703657815981" />
      <inertia
        ixx="2.52245584966873E-07"
        ixy="1.71914758712969E-10"
        ixz="-1.64919831961142E-08"
        iyy="2.28558868905267E-07"
        iyz="5.61508176325026E-10"
        izz="1.66029764061523E-07" />
    </inertial>
    <visual>
      <origin
        xyz="0 0 0"
        rpy="0 0 0" />
      <geometry>
        <mesh
          filename="meshes/middle_metacarpals.STL" />
      </geometry>
      <material
        name="">
        <color
          rgba="0.792156862745098 0.819607843137255 0.933333333333333 1" />
      </material>
    </visual>
    <collision>
      <origin
        xyz="0 0 0"
        rpy="0 0 0" />
      <geometry>
        <mesh
          filename="meshes/middle_metacarpals.STL" />
      </geometry>
    </collision>
  </link>
  <joint
    name="middle_mcp_roll"
    type="revolute">
    <origin
      xyz="-0.000558750127642211 0.00199999999999996 0.0687193135351955"
      rpy="0 0 0" />
    <parent
      link="base_link" />
    <child
      link="middle_metacarpals" />
    <axis
      xyz="1 0 0" />
    <limit
      lower="-0.26"
      upper="0.26"
      effort="1"
      velocity="1" />
  </joint>
  <link
    name="middle_proximal">
    <inertial>
      <origin
        xyz="-0.000597387569923995 9.14921175449817E-05 0.0170944627525956"
        rpy="0 0 0" />
      <mass
        value="0.00507606848812129" />
      <inertia
        ixx="7.97737112921743E-07"
        ixy="4.37945379660437E-10"
        ixz="1.8446548839231E-08"
        iyy="7.76379250187632E-07"
        iyz="6.51012928008541E-09"
        izz="2.00741368938845E-07" />
    </inertial>
    <visual>
      <origin
        xyz="0 0 0"
        rpy="0 0 0" />
      <geometry>
        <mesh
          filename="meshes/middle_proximal.STL" />
      </geometry>
      <material
        name="">
        <color
          rgba="0.792156862745098 0.819607843137255 0.933333333333333 1" />
      </material>
    </visual>
    <collision>
      <origin
        xyz="0 0 0"
        rpy="0 0 0" />
      <geometry>
        <mesh
          filename="meshes/middle_proximal.STL" />
      </geometry>
    </collision>
  </link>
  <joint
    name="middle_mcp_pitch"
    type="revolute">
    <origin
      xyz="0.00205000000000069 -0.000161569543388175 0.016999232196857"
      rpy="0.00950423387383179 0 0" />
    <parent
      link="middle_metacarpals" />
    <child
      link="middle_proximal" />
    <axis
      xyz="0 1 0" />
    <limit
      lower="0"
      upper="1.45"
      effort="1"
      velocity="1" />
  </joint>
  <link
    name="middle_middle">
    <inertial>
      <origin
        xyz="-0.000148343358137275 1.6229060517171E-05 0.0129647620091407"
        rpy="0 0 0" />
      <mass
        value="0.00351907493344208" />
      <inertia
        ixx="4.05670154245459E-07"
        ixy="-1.88873006229651E-10"
        ixz="1.34821565732684E-08"
        iyy="3.87446195025304E-07"
        iyz="4.30756497642751E-10"
        izz="1.24615611075233E-07" />
    </inertial>
    <visual>
      <origin
        xyz="0 0 0"
        rpy="0 0 0" />
      <geometry>
        <mesh
          filename="meshes/middle_middle.STL" />
      </geometry>
      <material
        name="">
        <color
          rgba="0.792156862745098 0.819607843137255 0.933333333333333 1" />
      </material>
    </visual>
    <collision>
      <origin
        xyz="0 0 0"
        rpy="0 0 0" />
      <geometry>
        <mesh
          filename="meshes/middle_middle.STL" />
      </geometry>
    </collision>
  </link>
  <joint
    name="middle_pip"
    type="revolute">
    <origin
      xyz="5.89757156506249E-05 0 0.0374777367297524"
      rpy="0 0 0" />
    <parent
      link="middle_proximal" />
    <child
      link="middle_middle" />
    <axis
      xyz="0 1 0" />
    <limit
      lower="0"
      upper="1.45"
      effort="1"
      velocity="1" />
  </joint>
  <link
    name="middle_distal">
    <inertial>
      <origin
        xyz="-0.00172222787983845 5.76849977571145E-06 0.0106139259055365"
        rpy="0 0 0" />
      <mass
        value="0.00300862444672732" />
      <inertia
        ixx="1.59990060388022E-07"
        ixy="-2.79688533266781E-12"
        ixz="3.62747785657225E-08"
        iyy="1.52389907319727E-07"
        iyz="-6.84744076323599E-12"
        izz="7.39573692701429E-08" />
    </inertial>
    <visual>
      <origin
        xyz="0 0 0"
        rpy="0 0 0" />
      <geometry>
        <mesh
          filename="meshes/middle_distal.STL" />
      </geometry>
      <material
        name="">
        <color
          rgba="0.792156862745098 0.819607843137255 0.933333333333333 1" />
      </material>
    </visual>
    <collision>
      <origin
        xyz="0 0 0"
        rpy="0 0 0" />
      <geometry>
        <mesh
          filename="meshes/middle_distal.STL" />
      </geometry>
    </collision>
  </link>
  <joint
    name="middle_dip"
    type="revolute">
    <origin
      xyz="4.60008788725467E-05 0 0.029232520686218"
      rpy="0 0 0" />
    <parent
      link="middle_middle" />
    <child
      link="middle_distal" />
    <axis
      xyz="0 1 0" />
    <limit
      lower="0"
      upper="1.45"
      effort="1"
      velocity="1" />
  </joint>
  <link
    name="index_metacarpals">
    <inertial>
      <origin
        xyz="0.000604992462815462 0.000390475031597566 0.00923622036768993"
        rpy="0 0 0" />
      <mass
        value="0.00336703681682743" />
      <inertia
        ixx="2.52245598042782E-07"
        ixy="-6.87103646340949E-10"
        ixz="-1.6478555495494E-08"
        iyy="2.28447717393264E-07"
        iyz="-2.69321575039201E-09"
        izz="1.66140925367234E-07" />
    </inertial>
    <visual>
      <origin
        xyz="0 0 0"
        rpy="0 0 0" />
      <geometry>
        <mesh
          filename="meshes/index_metacarpals.STL" />
      </geometry>
      <material
        name="">
        <color
          rgba="0.792156862745098 0.819607843137255 0.933333333333333 1" />
      </material>
    </visual>
    <collision>
      <origin
        xyz="0 0 0"
        rpy="0 0 0" />
      <geometry>
        <mesh
          filename="meshes/index_metacarpals.STL" />
      </geometry>
    </collision>
  </link>
  <joint
    name="index_mcp_roll"
    type="revolute">
    <origin
      xyz="0.00135314269572811 0.0262634482323828 0.0638497239660517"
      rpy="0.00130397490498434 -0.0151350137208889 -0.0859472581237413" />
    <parent
      link="base_link" />
    <child
      link="index_metacarpals" />
    <axis
      xyz="1 0 0" />
    <limit
      lower="-0.26"
      upper="0.26"
      effort="1"
      velocity="1" />
  </joint>
  <link
    name="index_proximal">
    <inertial>
      <origin
        xyz="-0.000856299257843096 9.14908805367334E-05 0.0170834091443181"
        rpy="0 0 0" />
      <mass
        value="0.00507604721014978" />
      <inertia
        ixx="7.97038033711248E-07"
        ixy="3.39661133954026E-10"
        ixz="2.74813761319766E-08"
        iyy="7.7637621986233E-07"
        iyz="6.51624500268013E-09"
        izz="2.01435984073942E-07" />
    </inertial>
    <visual>
      <origin
        xyz="0 0 0"
        rpy="0 0 0" />
      <geometry>
        <mesh
          filename="meshes/index_proximal.STL" />
      </geometry>
      <material
        name="">
        <color
          rgba="0.792156862745098 0.819607843137255 0.933333333333333 1" />
      </material>
    </visual>
    <collision>
      <origin
        xyz="0 0 0"
        rpy="0 0 0" />
      <geometry>
        <mesh
          filename="meshes/index_proximal.STL" />
      </geometry>
    </collision>
  </link>
  <joint
    name="index_mcp_pitch"
    type="revolute">
    <origin
      xyz="0.00205000000000052 0.000723853327462082 0.0169845823133896"
      rpy="-0.0425973654908491 0.0151341825120528 -0.000645041802587545" />
    <parent
      link="index_metacarpals" />
    <child
      link="index_proximal" />
    <axis
      xyz="0 1 0" />
    <limit
      lower="0"
      upper="1.45"
      effort="1"
      velocity="1" />
  </joint>
  <link
    name="index_middle">
    <inertial>
      <origin
        xyz="-0.000344722082964915 1.61264217699783E-05 0.0129609933233212"
        rpy="0 0 0" />
      <mass
        value="0.0035191208790441" />
      <inertia
        ixx="4.05199844080222E-07"
        ixy="-1.951695172344E-10"
        ixz="1.77328119208625E-08"
        iyy="3.87448112052797E-07"
        iyz="4.26691874690543E-10"
        izz="1.25089734619731E-07" />
    </inertial>
    <visual>
      <origin
        xyz="0 0 0"
        rpy="0 0 0" />
      <geometry>
        <mesh
          filename="meshes/index_middle.STL" />
      </geometry>
      <material
        name="">
        <color
          rgba="0.792156862745098 0.819607843137255 0.933333333333333 1" />
      </material>
    </visual>
    <collision>
      <origin
        xyz="0 0 0"
        rpy="0 0 0" />
      <geometry>
        <mesh
          filename="meshes/index_middle.STL" />
      </geometry>
    </collision>
  </link>
  <joint
    name="index_pip"
    type="revolute">
    <origin
      xyz="-0.00050871915574823 0 0.0374743303254407"
      rpy="0 0 0" />
    <parent
      link="index_proximal" />
    <child
      link="index_middle" />
    <axis
      xyz="0 1 0" />
    <limit
      lower="0"
      upper="1.45"
      effort="1"
      velocity="1" />
  </joint>
  <link
    name="index_distal">
    <inertial>
      <origin
        xyz="-0.00188281818999244 5.8014148869405E-06 0.0105864088242598"
        rpy="0 0 0" />
      <mass
        value="0.00300858925817878" />
      <inertia
        ixx="1.58870195401158E-07"
        ixy="-3.00527167289838E-12"
        ixz="3.75611390530122E-08"
        iyy="1.52388967145473E-07"
        iyz="-7.30105348458548E-12"
        izz="7.50762072321051E-08" />
    </inertial>
    <visual>
      <origin
        xyz="0 0 0"
        rpy="0 0 0" />
      <geometry>
        <mesh
          filename="meshes/index_distal.STL" />
      </geometry>
      <material
        name="">
        <color
          rgba="0.792156862745098 0.819607843137255 0.933333333333333 1" />
      </material>
    </visual>
    <collision>
      <origin
        xyz="0 0 0"
        rpy="0 0 0" />
      <geometry>
        <mesh
          filename="meshes/index_distal.STL" />
      </geometry>
    </collision>
  </link>
  <joint
    name="index_dip"
    type="revolute">
    <origin
      xyz="-0.000396799394561585 0 0.0292298637012133"
      rpy="0 0 0" />
    <parent
      link="index_middle" />
    <child
      link="index_distal" />
    <axis
      xyz="0 1 0" />
    <limit
      lower="0"
      upper="1.45"
      effort="1"
      velocity="1" />
  </joint>
  <link
    name="thumb_metacarpals_base2">
    <inertial>
      <origin
        xyz="-0.0015314070371433 -0.000187190106206825 -0.00155942986697459"
        rpy="0 0 0" />
      <mass
        value="0.00538827088538427" />
      <inertia
        ixx="4.01389736096669E-07"
        ixy="1.07747459442345E-09"
        ixz="8.95605323902379E-09"
        iyy="7.31124536864558E-07"
        iyz="3.03201113772735E-08"
        izz="9.80364928512913E-07" />
    </inertial>
    <visual>
      <origin
        xyz="0 0 0"
        rpy="0 0 0" />
      <geometry>
        <mesh
          filename="meshes/thumb_metacarpals_base2.STL" />
      </geometry>
      <material
        name="">
        <color
          rgba="0.792156862745098 0.819607843137255 0.933333333333333 1" />
      </material>
    </visual>
    <collision>
      <origin
        xyz="0 0 0"
        rpy="0 0 0" />
      <geometry>
        <mesh
          filename="meshes/thumb_metacarpals_base2.STL" />
      </geometry>
    </collision>
  </link>
  <joint
    name="thumb_cmc_yaw"
    type="revolute">
    <origin
      xyz="0.018841197752086 0.0319735834828885 0.0285096506505706"
      rpy="-1.33049483947685 1.02960836603009 -1.36378504932323" />
    <parent
      link="base_link" />
    <child
      link="thumb_metacarpals_base2" />
    <axis
      xyz="1 0 0" />
    <limit
      lower="-0.79"
      upper="0.79"
      effort="1"
      velocity="1" />
  </joint>
  <link
    name="thumb_metacarpals">
    <inertial>
      <origin
        xyz="-0.000483092938663564 -0.000366098418731767 0.0156599779124304"
        rpy="0 0 0" />
      <mass
        value="0.0085792246033564" />
      <inertia
        ixx="9.96297032970078E-07"
        ixy="-1.97312910953245E-08"
        ixz="5.95021444537226E-08"
        iyy="9.64717390983825E-07"
        iyz="-1.17024247702618E-08"
        izz="5.16983935718461E-07" />
    </inertial>
    <visual>
      <origin
        xyz="0 0 0"
        rpy="0 0 0" />
      <geometry>
        <mesh
          filename="meshes/thumb_metacarpals.STL" />
      </geometry>
      <material
        name="">
        <color
          rgba="0.792156862745098 0.819607843137255 0.933333333333333 1" />
      </material>
    </visual>
    <collision>
      <origin
        xyz="0 0 0"
        rpy="0 0 0" />
      <geometry>
        <mesh
          filename="meshes/thumb_metacarpals.STL" />
      </geometry>
    </collision>
  </link>
  <joint
    name="thumb_cmc_pitch"
    type="revolute">
    <origin
      xyz="0.0035 0 0"
      rpy="0.45118 -0.11931 -1.5708" />
    <parent
      link="thumb_metacarpals_base2" />
    <child
      link="thumb_metacarpals" />
    <axis
      xyz="-1 0 0" />
    <limit
      lower="0"
      upper="0.79"
      effort="1"
      velocity="1" />
  </joint>
  <link
    name="thumb_proximal">
    <inertial>
      <origin
        xyz="-0.000253930462336394 3.85768527323572E-05 0.0174889749560033"
        rpy="0 0 0" />
      <mass
        value="0.00724406588531127" />
      <inertia
        ixx="1.40355793704461E-06"
        ixy="-5.13590891756812E-10"
        ixz="4.80495651561954E-08"
        iyy="1.32197865824667E-06"
        iyz="5.49467953942175E-09"
        izz="4.41729204914362E-07" />
    </inertial>
    <visual>
      <origin
        xyz="0 0 0"
        rpy="0 0 0" />
      <geometry>
        <mesh
          filename="meshes/thumb_proximal.STL" />
      </geometry>
      <material
        name="">
        <color
          rgba="0.792156862745098 0.819607843137255 0.933333333333333 1" />
      </material>
    </visual>
    <collision>
      <origin
        xyz="0 0 0"
        rpy="0 0 0" />
      <geometry>
        <mesh
          filename="meshes/thumb_proximal.STL" />
      </geometry>
    </collision>
  </link>
  <joint
    name="thumb_mcp"
    type="revolute">
    <origin
      xyz="-5.35741531505693E-05 -0.000855144006936749 0.0324421622838387"
      rpy="0.0206111996188077 -0.0161285471258008 -0.349480836393033" />
    <parent
      link="thumb_metacarpals" />
    <child
      link="thumb_proximal" />
    <axis
      xyz="0 1 0" />
    <limit
      lower="0"
      upper="1.45"
      effort="1"
      velocity="1" />
  </joint>
  <link
    name="thumb_distal">
    <inertial>
      <origin
        xyz="-0.00232042627893438 1.76687753801266E-05 0.0138185232424426"
        rpy="0 0 0" />
      <mass
        value="0.00700367417691828" />
      <inertia
        ixx="6.19744859247405E-07"
        ixy="-1.04577508355539E-09"
        ixz="1.50968972143638E-07"
        iyy="6.11901892567194E-07"
        iyz="1.47106233921328E-09"
        izz="3.01260748816888E-07" />
    </inertial>
    <visual>
      <origin
        xyz="0 0 0"
        rpy="0 0 0" />
      <geometry>
        <mesh
          filename="meshes/thumb_distal.STL" />
      </geometry>
      <material
        name="">
        <color
          rgba="0.792156862745098 0.819607843137255 0.933333333333333 1" />
      </material>
    </visual>
    <collision>
      <origin
        xyz="0 0 0"
        rpy="0 0 0" />
      <geometry>
        <mesh
          filename="meshes/thumb_distal.STL" />
      </geometry>
    </collision>
  </link>
  <joint
    name="thumb_ip"
    type="revolute">
    <origin
      xyz="-0.000519512586156273 0 0.0378509365620059"
      rpy="0 0 0" />
    <parent
      link="thumb_proximal" />
    <child
      link="thumb_distal" />
    <axis
      xyz="0 1 0" />
    <limit
      lower="0"
      upper="1.45"
      effort="1"
      velocity="1" />
  </joint>
</robot>