<?xml version="1.0" encoding="utf-8"?>
<!-- This URDF was automatically created by SolidWorks to URDF Exporter! Originally created by Stephen Brawner (brawner@gmail.com) 
     Commit Version: 1.6.0-4-g7f85cfe  Build Version: 1.6.7995.38578
     For more information, please see http://wiki.ros.org/sw_urdf_exporter -->
<robot
  name="linker_l20_right_v9.0_urdf">
  <link
    name="base_link">
    <inertial>
      <origin
        xyz="-0.011620261826289 -0.00274408052916145 0.0887470796714767"
        rpy="0 0 0" />
      <mass
        value="0.11937688599385" />
      <inertia
        ixx="0.000281631012191348"
        ixy="-8.32650755459043E-07"
        ixz="1.21226290989181E-05"
        iyy="0.000193306068615882"
        iyz="-4.50732810047053E-07"
        izz="0.000103641849373219" />
    </inertial>
    <visual>
      <origin
        xyz="0 0 0"
        rpy="0 0 0" />
      <geometry>
        <mesh
          filename="meshes/base_link.STL" />
      </geometry>
      <material
        name="">
        <color
          rgba="1 1 1 1" />
      </material>
    </visual>
    <collision>
      <origin
        xyz="0 0 0"
        rpy="0 0 0" />
      <geometry>
        <mesh
          filename="meshes/base_link.STL" />
      </geometry>
    </collision>
  </link>
  <link
    name="pinky_metacarpals">
    <inertial>
      <origin
        xyz="0.0111783602812616 9.71805658167568E-09 0.00220159774985697"
        rpy="0 0 0" />
      <mass
        value="0.000876740424974171" />
      <inertia
        ixx="3.50685796605318E-08"
        ixy="2.37969995283725E-13"
        ixz="-5.24778032378607E-09"
        iyy="2.68809612615393E-08"
        iyz="4.22813805139068E-14"
        izz="4.23561171499408E-08" />
    </inertial>
    <visual>
      <origin
        xyz="0 0 0"
        rpy="0 0 0" />
      <geometry>
        <mesh
          filename="meshes/pinky_metacarpals.STL" />
      </geometry>
      <material
        name="">
        <color
          rgba="1 1 1 1" />
      </material>
    </visual>
    <collision>
      <origin
        xyz="0 0 0"
        rpy="0 0 0" />
      <geometry>
        <mesh
          filename="meshes/pinky_metacarpals.STL" />
      </geometry>
    </collision>
  </link>
  <joint
    name="pinky_mcp_roll"
    type="revolute">
    <origin
      xyz="-0.028575599600215 -0.0381024421136991 0.150312739930038"
      rpy="0 0 0" />
    <parent
      link="base_link" />
    <child
      link="pinky_metacarpals" />
    <axis
      xyz="0.999999999998204 0 0" />
    <limit
      lower="-0.17"
      upper="0.17"
      effort="1"
      velocity="1" />
  </joint>
  <link
    name="pinky_proximal">
    <inertial>
      <origin
        xyz="-0.00112895839994493 -3.79145600554187E-06 0.0228398814721952"
        rpy="0 0 0" />
      <mass
        value="0.00451760212331234" />
      <inertia
        ixx="6.69993733698809E-07"
        ixy="-1.01449716218779E-11"
        ixz="2.60703311997585E-08"
        iyy="6.78893091787921E-07"
        iyz="-1.54607175246649E-10"
        izz="1.37491573213612E-07" />
    </inertial>
    <visual>
      <origin
        xyz="0 0 0"
        rpy="0 0 0" />
      <geometry>
        <mesh
          filename="meshes/pinky_proximal.STL" />
      </geometry>
      <material
        name="">
        <color
          rgba="1 1 1 1" />
      </material>
    </visual>
    <collision>
      <origin
        xyz="0 0 0"
        rpy="0 0 0" />
      <geometry>
        <mesh
          filename="meshes/pinky_proximal.STL" />
      </geometry>
    </collision>
  </link>
  <joint
    name="pinky_mcp_pitch"
    type="revolute">
    <origin
      xyz="0.0166748095648401 0 0"
      rpy="0 0 0" />
    <parent
      link="pinky_metacarpals" />
    <child
      link="pinky_proximal" />
    <axis
      xyz="0 1 0" />
    <limit
      lower="0"
      upper="1.4"
      effort="1"
      velocity="1" />
  </joint>
  <link
    name="pinky_middle">
    <inertial>
      <origin
        xyz="-0.000211169706509542 -2.59533084201458E-06 0.0168377462832341"
        rpy="0 0 0" />
      <mass
        value="0.00240726454050251" />
      <inertia
        ixx="2.37166762597919E-07"
        ixy="-8.40854168436704E-13"
        ixz="1.39313946202203E-08"
        iyy="1.83336939185043E-07"
        iyz="6.98408572116134E-13"
        izz="9.82233286360317E-08" />
    </inertial>
    <visual>
      <origin
        xyz="0 0 0"
        rpy="0 0 0" />
      <geometry>
        <mesh
          filename="meshes/pinky_middle.STL" />
      </geometry>
      <material
        name="">
        <color
          rgba="1 1 1 1" />
      </material>
    </visual>
    <collision>
      <origin
        xyz="0 0 0"
        rpy="0 0 0" />
      <geometry>
        <mesh
          filename="meshes/pinky_middle.STL" />
      </geometry>
    </collision>
  </link>
  <joint
    name="pinky_pip"
    type="revolute">
    <origin
      xyz="-0.00419455244191127 1.32099958100595E-05 0.0448194355633776"
      rpy="0 0 0" />
    <parent
      link="pinky_proximal" />
    <child
      link="pinky_middle" />
    <axis
      xyz="0 1 0" />
    <limit
      lower="0"
      upper="1.57"
      effort="1"
      velocity="1" />
  </joint>
  <link
    name="pinky_distal">
    <inertial>
      <origin
        xyz="-0.00807029340145454 -1.93501202306046E-05 0.00803089258129761"
        rpy="0 0 0" />
      <mass
        value="0.00337425966640625" />
      <inertia
        ixx="1.62072520517533E-07"
        ixy="1.01331520983936E-10"
        ixz="5.9624392404289E-08"
        iyy="1.79093091317115E-07"
        iyz="-1.04733372031767E-10"
        izz="1.32918893464252E-07" />
    </inertial>
    <visual>
      <origin
        xyz="0 0 0"
        rpy="0 0 0" />
      <geometry>
        <mesh
          filename="meshes/pinky_distal.STL" />
      </geometry>
      <material
        name="">
        <color
          rgba="1 1 1 1" />
      </material>
    </visual>
    <collision>
      <origin
        xyz="0 0 0"
        rpy="0 0 0" />
      <geometry>
        <mesh
          filename="meshes/pinky_distal.STL" />
      </geometry>
    </collision>
  </link>
  <joint
    name="pinky_dip"
    type="revolute">
    <origin
      xyz="0.00275561956448663 0 0.0317024252339038"
      rpy="0 0 0" />
    <parent
      link="pinky_middle" />
    <child
      link="pinky_distal" />
    <axis
      xyz="0 1 0" />
    <limit
      lower="0"
      upper="1.4"
      effort="1"
      velocity="1" />
    <mimic
      joint="pinky_pip"
      multiplier="0.8917"
      offset="0" />
  </joint>
  <link
    name="ring_metacarpals">
    <inertial>
      <origin
        xyz="0.0111783602812615 -5.44586388928625E-07 0.00220163628642245"
        rpy="0 0 0" />
      <mass
        value="0.000876740424974176" />
      <inertia
        ixx="3.5068579660532E-08"
        ixy="2.37969995276923E-13"
        ixz="-5.24778032378599E-09"
        iyy="2.68809612615393E-08"
        iyz="4.22813803938397E-14"
        izz="4.23561171499408E-08" />
    </inertial>
    <visual>
      <origin
        xyz="0 0 0"
        rpy="0 0 0" />
      <geometry>
        <mesh
          filename="meshes/ring_metacarpals.STL" />
      </geometry>
      <material
        name="">
        <color
          rgba="1 1 1 1" />
      </material>
    </visual>
    <collision>
      <origin
        xyz="0 0 0"
        rpy="0 0 0" />
      <geometry>
        <mesh
          filename="meshes/ring_metacarpals.STL" />
      </geometry>
    </collision>
  </link>
  <joint
    name="ring_mcp_roll"
    type="revolute">
    <origin
      xyz="-0.0321993698689908 -0.0165018864843229 0.159311421874683"
      rpy="0 0 0" />
    <parent
      link="base_link" />
    <child
      link="ring_metacarpals" />
    <axis
      xyz="0.999999999998204 0 0" />
    <limit
      lower="-0.17"
      upper="0.17"
      effort="1"
      velocity="1" />
  </joint>
  <link
    name="ring_proximal">
    <inertial>
      <origin
        xyz="-0.00955921558507311 -1.70016755791369E-05 0.0148398984163987"
        rpy="0 0 0" />
      <mass
        value="0.00451760195794046" />
      <inertia
        ixx="6.69993722821465E-07"
        ixy="-1.01474386915083E-11"
        ixz="2.60703333666604E-08"
        iyy="6.78893086540266E-07"
        iyz="-1.54612724483144E-10"
        izz="1.37491565753842E-07" />
    </inertial>
    <visual>
      <origin
        xyz="0 0 0"
        rpy="0 0 0" />
      <geometry>
        <mesh
          filename="meshes/ring_proximal.STL" />
      </geometry>
      <material
        name="">
        <color
          rgba="1 1 1 1" />
      </material>
    </visual>
    <collision>
      <origin
        xyz="0 0 0"
        rpy="0 0 0" />
      <geometry>
        <mesh
          filename="meshes/ring_proximal.STL" />
      </geometry>
    </collision>
  </link>
  <joint
    name="ring_mcp_pitch"
    type="revolute">
    <origin
      xyz="0.0251050665600563 1.26716622367851E-05 0.00800002169746956"
      rpy="0 0 0" />
    <parent
      link="ring_metacarpals" />
    <child
      link="ring_proximal" />
    <axis
      xyz="0 1 0" />
    <limit
      lower="0"
      upper="1.4"
      effort="1"
      velocity="1" />
  </joint>
  <link
    name="ring_middle">
    <inertial>
      <origin
        xyz="-0.000211169680034644 -2.59524552165269E-06 0.0168377464520879"
        rpy="0 0 0" />
      <mass
        value="0.00240726457456344" />
      <inertia
        ixx="2.37166764775183E-07"
        ixy="-8.42216406451178E-13"
        ixz="1.3931392891153E-08"
        iyy="1.83336942110529E-07"
        iyz="6.95953123215741E-13"
        izz="9.82233292198863E-08" />
    </inertial>
    <visual>
      <origin
        xyz="0 0 0"
        rpy="0 0 0" />
      <geometry>
        <mesh
          filename="meshes/ring_middle.STL" />
      </geometry>
      <material
        name="">
        <color
          rgba="1 1 1 1" />
      </material>
    </visual>
    <collision>
      <origin
        xyz="0 0 0"
        rpy="0 0 0" />
      <geometry>
        <mesh
          filename="meshes/ring_middle.STL" />
      </geometry>
    </collision>
  </link>
  <joint
    name="ring_pip"
    type="revolute">
    <origin
      xyz="-0.0126248094619703 0 0.0368194524036704"
      rpy="0 0 0" />
    <parent
      link="ring_proximal" />
    <child
      link="ring_middle" />
    <axis
      xyz="0 1 0" />
    <limit
      lower="0"
      upper="1.57"
      effort="1"
      velocity="1" />
  </joint>
  <link
    name="ring_distal">
    <inertial>
      <origin
        xyz="-0.00807029340156035 -1.93501210593028E-05 0.00803089181817565"
        rpy="0 0 0" />
      <mass
        value="0.00337425966600315" />
      <inertia
        ixx="1.62072520497108E-07"
        ixy="1.01331470012741E-10"
        ixz="5.96243924070343E-08"
        iyy="1.79093091237455E-07"
        iyz="-1.04733393393394E-10"
        izz="1.32918893476288E-07" />
    </inertial>
    <visual>
      <origin
        xyz="0 0 0"
        rpy="0 0 0" />
      <geometry>
        <mesh
          filename="meshes/ring_distal.STL" />
      </geometry>
      <material
        name="">
        <color
          rgba="1 1 1 1" />
      </material>
    </visual>
    <collision>
      <origin
        xyz="0 0 0"
        rpy="0 0 0" />
      <geometry>
        <mesh
          filename="meshes/ring_distal.STL" />
      </geometry>
    </collision>
  </link>
  <joint
    name="ring_dip"
    type="revolute">
    <origin
      xyz="0.00275561956405355 0 0.0317024252327154"
      rpy="0 0 0" />
    <parent
      link="ring_middle" />
    <child
      link="ring_distal" />
    <axis
      xyz="0 1 0" />
    <limit
      lower="0"
      upper="1.4"
      effort="1"
      velocity="1" />
    <mimic
      joint="ring_pip"
      multiplier="0.8917"
      offset="0" />
  </joint>
  <link
    name="middle_metacarpals">
    <inertial>
      <origin
        xyz="0.0111783602812616 -5.44586388762092E-07 0.0022016362864224"
        rpy="0 0 0" />
      <mass
        value="0.000876740424974166" />
      <inertia
        ixx="3.50685796605316E-08"
        ixy="2.37969995601852E-13"
        ixz="-5.24778032378604E-09"
        iyy="2.68809612615391E-08"
        iyz="4.22813799331105E-14"
        izz="4.23561171499406E-08" />
    </inertial>
    <visual>
      <origin
        xyz="0 0 0"
        rpy="0 0 0" />
      <geometry>
        <mesh
          filename="meshes/middle_metacarpals.STL" />
      </geometry>
      <material
        name="">
        <color
          rgba="1 1 1 1" />
      </material>
    </visual>
    <collision>
      <origin
        xyz="0 0 0"
        rpy="0 0 0" />
      <geometry>
        <mesh
          filename="meshes/middle_metacarpals.STL" />
      </geometry>
    </collision>
  </link>
  <joint
    name="middle_mcp_roll"
    type="revolute">
    <origin
      xyz="-0.0345042006792679 0.00509811417717426 0.163804307612682"
      rpy="0 0 0" />
    <parent
      link="base_link" />
    <child
      link="middle_metacarpals" />
    <axis
      xyz="0.999999999998204 0 0" />
    <limit
      lower="-0.17"
      upper="0.17"
      effort="1"
      velocity="1" />
  </joint>
  <link
    name="middle_proximal">
    <inertial>
      <origin
        xyz="-0.0095592154289316 -1.70014495338155E-05 0.0148398983134099"
        rpy="0 0 0" />
      <mass
        value="0.00451760211910452" />
      <inertia
        ixx="6.69993733596981E-07"
        ixy="-1.01450009530961E-11"
        ixz="2.60703311569988E-08"
        iyy="6.78893091681914E-07"
        iyz="-1.54607004511646E-10"
        izz="1.37491573176307E-07" />
    </inertial>
    <visual>
      <origin
        xyz="0 0 0"
        rpy="0 0 0" />
      <geometry>
        <mesh
          filename="meshes/middle_proximal.STL" />
      </geometry>
      <material
        name="">
        <color
          rgba="1 1 1 1" />
      </material>
    </visual>
    <collision>
      <origin
        xyz="0 0 0"
        rpy="0 0 0" />
      <geometry>
        <mesh
          filename="meshes/middle_proximal.STL" />
      </geometry>
    </collision>
  </link>
  <joint
    name="middle_mcp_pitch"
    type="revolute">
    <origin
      xyz="0.0251050665601614 1.26716622368406E-05 0.00800002169696733"
      rpy="0 0 0" />
    <parent
      link="middle_metacarpals" />
    <child
      link="middle_proximal" />
    <axis
      xyz="0 1 0" />
    <limit
      lower="0"
      upper="1.4"
      effort="1"
      velocity="1" />
  </joint>
  <link
    name="middle_middle">
    <inertial>
      <origin
        xyz="-0.000211169788266033 -2.59530434057464E-06 0.0168377462566504"
        rpy="0 0 0" />
      <mass
        value="0.00240726449346529" />
      <inertia
        ixx="2.37166758883316E-07"
        ixy="-8.41669264093796E-13"
        ixz="1.39313950743123E-08"
        iyy="1.83336936162719E-07"
        iyz="6.97202665239409E-13"
        izz="9.82233268582599E-08" />
    </inertial>
    <visual>
      <origin
        xyz="0 0 0"
        rpy="0 0 0" />
      <geometry>
        <mesh
          filename="meshes/middle_middle.STL" />
      </geometry>
      <material
        name="">
        <color
          rgba="1 1 1 1" />
      </material>
    </visual>
    <collision>
      <origin
        xyz="0 0 0"
        rpy="0 0 0" />
      <geometry>
        <mesh
          filename="meshes/middle_middle.STL" />
      </geometry>
    </collision>
  </link>
  <joint
    name="middle_pip"
    type="revolute">
    <origin
      xyz="-0.0126248094622216 0 0.0368194524061594"
      rpy="0 0 0" />
    <parent
      link="middle_proximal" />
    <child
      link="middle_middle" />
    <axis
      xyz="0 1 0" />
    <limit
      lower="0"
      upper="1.57"
      effort="1"
      velocity="1" />
  </joint>
  <link
    name="middle_distal">
    <inertial>
      <origin
        xyz="-0.00807029340000556 -1.93501205603408E-05 0.00803089258473687"
        rpy="0 0 0" />
      <mass
        value="0.00337425966615046" />
      <inertia
        ixx="1.62072520444378E-07"
        ixy="1.01331478760051E-10"
        ixz="5.96243924035914E-08"
        iyy="1.79093091275449E-07"
        iyz="-1.04733397727201E-10"
        izz="1.32918893459179E-07" />
    </inertial>
    <visual>
      <origin
        xyz="0 0 0"
        rpy="0 0 0" />
      <geometry>
        <mesh
          filename="meshes/middle_distal.STL" />
      </geometry>
      <material
        name="">
        <color
          rgba="1 1 1 1" />
      </material>
    </visual>
    <collision>
      <origin
        xyz="0 0 0"
        rpy="0 0 0" />
      <geometry>
        <mesh
          filename="meshes/middle_distal.STL" />
      </geometry>
    </collision>
  </link>
  <joint
    name="middle_dip"
    type="revolute">
    <origin
      xyz="0.00275561956368908 0 0.031702425228504"
      rpy="0 0 0" />
    <parent
      link="middle_middle" />
    <child
      link="middle_distal" />
    <axis
      xyz="0 1 0" />
    <limit
      lower="0"
      upper="1.4"
      effort="1"
      velocity="1" />
    <mimic
      joint="middle_pip"
      multiplier="0.8917"
      offset="0" />
  </joint>
  <link
    name="index_metacarpals">
    <inertial>
      <origin
        xyz="0.0111783602812616 -5.44586388873114E-07 0.00220163628642246"
        rpy="0 0 0" />
      <mass
        value="0.000876740424974179" />
      <inertia
        ixx="3.50685796605321E-08"
        ixy="2.37969995333639E-13"
        ixz="-5.24778032378605E-09"
        iyy="2.68809612615395E-08"
        iyz="4.22813804036855E-14"
        izz="4.2356117149941E-08" />
    </inertial>
    <visual>
      <origin
        xyz="0 0 0"
        rpy="0 0 0" />
      <geometry>
        <mesh
          filename="meshes/index_metacarpals.STL" />
      </geometry>
      <material
        name="">
        <color
          rgba="1 1 1 1" />
      </material>
    </visual>
    <collision>
      <origin
        xyz="0 0 0"
        rpy="0 0 0" />
      <geometry>
        <mesh
          filename="meshes/index_metacarpals.STL" />
      </geometry>
    </collision>
  </link>
  <joint
    name="index_mcp_roll"
    type="revolute">
    <origin
      xyz="-0.0297703583048348 0.026698113515616 0.159311418025823"
      rpy="0 0 0" />
    <parent
      link="base_link" />
    <child
      link="index_metacarpals" />
    <axis
      xyz="0.999999999998204 0 0" />
    <limit
      lower="-0.17"
      upper="0.17"
      effort="1"
      velocity="1" />
  </joint>
  <link
    name="index_proximal">
    <inertial>
      <origin
        xyz="-0.00112895840999541 -3.79145382717327E-06 0.0228398814738125"
        rpy="0 0 0" />
      <mass
        value="0.00451760211825835" />
      <inertia
        ixx="6.69993733567589E-07"
        ixy="-1.01449915953169E-11"
        ixz="2.6070331151262E-08"
        iyy="6.7889309165604E-07"
        iyz="-1.54607144938343E-10"
        izz="1.37491573165547E-07" />
    </inertial>
    <visual>
      <origin
        xyz="0 0 0"
        rpy="0 0 0" />
      <geometry>
        <mesh
          filename="meshes/index_proximal.STL" />
      </geometry>
      <material
        name="">
        <color
          rgba="1 1 1 1" />
      </material>
    </visual>
    <collision>
      <origin
        xyz="0 0 0"
        rpy="0 0 0" />
      <geometry>
        <mesh
          filename="meshes/index_proximal.STL" />
      </geometry>
    </collision>
  </link>
  <joint
    name="index_mcp_pitch"
    type="revolute">
    <origin
      xyz="0.0166748095646496 0 0"
      rpy="0 0 0" />
    <parent
      link="index_metacarpals" />
    <child
      link="index_proximal" />
    <axis
      xyz="0 1 0" />
    <limit
      lower="0"
      upper="1.4"
      effort="1"
      velocity="1" />
  </joint>
  <link
    name="index_middle">
    <inertial>
      <origin
        xyz="-0.000211169838065489 -2.5954094765579E-06 0.0168377460160872"
        rpy="0 0 0" />
      <mass
        value="0.00240726447718958" />
      <inertia
        ixx="2.37166756819848E-07"
        ixy="-8.40334954033228E-13"
        ixz="1.39313968245868E-08"
        iyy="1.8333693296862E-07"
        iyz="6.99644799463844E-13"
        izz="9.82233270278881E-08" />
    </inertial>
    <visual>
      <origin
        xyz="0 0 0"
        rpy="0 0 0" />
      <geometry>
        <mesh
          filename="meshes/index_middle.STL" />
      </geometry>
      <material
        name="">
        <color
          rgba="1 1 1 1" />
      </material>
    </visual>
    <collision>
      <origin
        xyz="0 0 0"
        rpy="0 0 0" />
      <geometry>
        <mesh
          filename="meshes/index_middle.STL" />
      </geometry>
    </collision>
  </link>
  <joint
    name="index_pip"
    type="revolute">
    <origin
      xyz="-0.00419455239160021 1.32099983796707E-05 0.0448194355727413"
      rpy="0 0 0" />
    <parent
      link="index_proximal" />
    <child
      link="index_middle" />
    <axis
      xyz="0 1 0" />
    <limit
      lower="0"
      upper="1.57"
      effort="1"
      velocity="1" />
  </joint>
  <link
    name="index_distal">
    <inertial>
      <origin
        xyz="-0.00807029340029854 -1.93501205141555E-05 0.00803089258454236"
        rpy="0 0 0" />
      <mass
        value="0.00337425966618635" />
      <inertia
        ixx="1.6207252045105E-07"
        ixy="1.01331477160975E-10"
        ixz="5.96243924026828E-08"
        iyy="1.79093091271022E-07"
        iyz="-1.04733396885457E-10"
        izz="1.32918893461444E-07" />
    </inertial>
    <visual>
      <origin
        xyz="0 0 0"
        rpy="0 0 0" />
      <geometry>
        <mesh
          filename="meshes/index_distal.STL" />
      </geometry>
      <material
        name="">
        <color
          rgba="1 1 1 1" />
      </material>
    </visual>
    <collision>
      <origin
        xyz="0 0 0"
        rpy="0 0 0" />
      <geometry>
        <mesh
          filename="meshes/index_distal.STL" />
      </geometry>
    </collision>
  </link>
  <joint
    name="index_dip"
    type="revolute">
    <origin
      xyz="0.00275561951363186 0 0.0317024252223218"
      rpy="0 0 0" />
    <parent
      link="index_middle" />
    <child
      link="index_distal" />
    <axis
      xyz="0 1 0" />
    <limit
      lower="0"
      upper="1.4"
      effort="1"
      velocity="1" />
    <mimic
      joint="index_pip"
      multiplier="0.8917"
      offset="0" />
  </joint>
  <link
    name="thumb_metacarpals_base1">
    <inertial>
      <origin
        xyz="0.00225238137571548 0.0106281730889677 0.00386563507860038"
        rpy="0 0 0" />
      <mass
        value="0.0123205476694916" />
      <inertia
        ixx="3.0840872491739E-06"
        ixy="7.90141615431144E-08"
        ixz="-5.00722594467121E-08"
        iyy="4.73446694039298E-06"
        iyz="1.89380820616155E-07"
        izz="2.03286521827113E-06" />
    </inertial>
    <visual>
      <origin
        xyz="0 0 0"
        rpy="0 0 0" />
      <geometry>
        <mesh
          filename="meshes/thumb_metacarpals_base1.STL" />
      </geometry>
      <material
        name="">
        <color
          rgba="1 1 1 1" />
      </material>
    </visual>
    <collision>
      <origin
        xyz="0 0 0"
        rpy="0 0 0" />
      <geometry>
        <mesh
          filename="meshes/thumb_metacarpals_base1.STL" />
      </geometry>
    </collision>
  </link>
  <joint
    name="thumb_cmc_yaw"
    type="revolute">
    <origin
      xyz="0.0039847 0.0050818 0.057392"
      rpy="3.1416 0 1.5708" />
    <parent
      link="base_link" />
    <child
      link="thumb_metacarpals_base1" />
    <axis
      xyz="0 1 0" />
    <limit
      lower="0"
      upper="1.4"
      effort="1"
      velocity="1" />
  </joint>
  <link
    name="thumb_metacarpals_base2">
    <inertial>
      <origin
        xyz="0.00119786541618824 0.00176299022707369 0.00980404243330507"
        rpy="0 0 0" />
      <mass
        value="0.00459772397289602" />
      <inertia
        ixx="7.31634903650296E-07"
        ixy="4.16930863500661E-08"
        ixz="-7.27796562010211E-08"
        iyy="5.38487447636595E-07"
        iyz="1.05405201691116E-07"
        izz="3.72564315942347E-07" />
    </inertial>
    <visual>
      <origin
        xyz="0 0 0"
        rpy="0 0 0" />
      <geometry>
        <mesh
          filename="meshes/thumb_metacarpals_base2.STL" />
      </geometry>
      <material
        name="">
        <color
          rgba="1 1 1 1" />
      </material>
    </visual>
    <collision>
      <origin
        xyz="0 0 0"
        rpy="0 0 0" />
      <geometry>
        <mesh
          filename="meshes/thumb_metacarpals_base2.STL" />
      </geometry>
    </collision>
  </link>
  <joint
    name="thumb_cmc_roll"
    type="revolute">
    <origin
      xyz="0.00078474 0.019608 0.00030872"
      rpy="1.1826 0 1.5708" />
    <parent
      link="thumb_metacarpals_base1" />
    <child
      link="thumb_metacarpals_base2" />
    <axis
      xyz="0 1 0" />
    <limit
      lower="0"
      upper="1.22"
      effort="1"
      velocity="1" />
  </joint>
  <link
    name="thumb_metacarpals">
    <inertial>en 
      <origin
        xyz="0.00549166823270433 0.00805301003186135 0.0258291613450025"
        rpy="0 0 0" />
      <mass
        value="0.0119766770700791" />
      <inertia
        ixx="4.12827715566723E-06"
        ixy="-2.09070693209702E-08"
        ixz="-1.79929143315225E-08"
        iyy="4.82188747454608E-06"
        iyz="-6.18428959857057E-08"
        izz="1.21403973338737E-06" />
    </inertial>
    <visual>
      <origin
        xyz="0 0 0"
        rpy="0 0 0" />
      <geometry>
        <mesh
          filename="meshes/thumb_metacarpals.STL" />
      </geometry>
      <material
        name="">
        <color
          rgba="1 1 1 1" />
      </material>
    </visual>
    <collision>
      <origin
        xyz="0 0 0"
        rpy="0 0 0" />
      <geometry>
        <mesh
          filename="meshes/thumb_metacarpals.STL" />
      </geometry>
    </collision>
  </link>
  <joint
    name="thumb_cmc_pitch"
    type="revolute">
    <origin
      xyz="-0.00010969 -0.0039644 0.030795"
      rpy="0 0.38815 -1.5708" />
    <parent
      link="thumb_metacarpals_base2" />
    <child
      link="thumb_metacarpals" />
    <axis
      xyz="0 1 0" />
    <limit
      lower="0"
      upper="0.79"
      effort="1"
      velocity="1" />
  </joint>
  <link
    name="thumb_proximal">
    <inertial>
      <origin
        xyz="-0.00110581154816419 0.000334168978806698 0.0128606460877002"
        rpy="0 0 0" />
      <mass
        value="0.00515934933952247" />
      <inertia
        ixx="4.56386382924756E-07"
        ixy="-1.15146110659666E-09"
        ixz="-8.11494572264421E-08"
        iyy="6.1631634624166E-07"
        iyz="-5.36276832530009E-09"
        izz="2.4690573764591E-07" />
    </inertial>
    <visual>
      <origin
        xyz="0 0 0"
        rpy="0 0 0" />
      <geometry>
        <mesh
          filename="meshes/thumb_proximal.STL" />
      </geometry>
      <material
        name="">
        <color
          rgba="1 1 1 1" />
      </material>
    </visual>
    <collision>
      <origin
        xyz="0 0 0"
        rpy="0 0 0" />
      <geometry>
        <mesh
          filename="meshes/thumb_proximal.STL" />
      </geometry>
    </collision>
  </link>
  <joint
    name="thumb_mcp"
    type="revolute">
    <origin
      xyz="0.0085786 0 0.055572"
      rpy="0 0 0" />
    <parent
      link="thumb_metacarpals" />
    <child
      link="thumb_proximal" />
    <axis
      xyz="0 1 0" />
    <limit
      lower="0"
      upper="1.05"
      effort="1"
      velocity="1" />
  </joint>
  <link
    name="thumb_distal">
    <inertial>
      <origin
        xyz="-0.00625056907004873 -0.00251546922629341 0.0132122489219003"
        rpy="0 0 0" />
      <mass
        value="0.00408969366280382" />
      <inertia
        ixx="2.36259669358736E-07"
        ixy="2.35860723267732E-09"
        ixz="6.44473102385798E-08"
        iyy="2.76662665184841E-07"
        iyz="-6.5752180911147E-09"
        izz="1.12752822786612E-07" />
    </inertial>
    <visual>
      <origin
        xyz="0 0 0"
        rpy="0 0 0" />
      <geometry>
        <mesh
          filename="meshes/thumb_distal.STL" />
      </geometry>
      <material
        name="">
        <color
          rgba="1 1 1 1" />
      </material>
    </visual>
    <collision>
      <origin
        xyz="0 0 0"
        rpy="0 0 0" />
      <geometry>
        <mesh
          filename="meshes/thumb_distal.STL" />
      </geometry>
    </collision>
  </link>
  <joint
    name="thumb_dip"
    type="revolute">
    <origin
      xyz="0.0066654 0 0.034256"
      rpy="0 0 0" />
    <parent
      link="thumb_proximal" />
    <child
      link="thumb_distal" />
    <axis
      xyz="0 1 0" />
    <limit
      lower="0"
      upper="1.22"
      effort="1"
      velocity="1" />
    <mimic
      joint="thumb_mcp"
      multiplier="1.1619"
      offset="0" />
  </joint>
</robot>