<?xml version="1.0" encoding="utf-8"?>
<!-- This URDF was automatically created by SolidWorks to URDF Exporter! Originally created by Stephen Brawner (brawner@gmail.com) 
     Commit Version: 1.6.0-1-g15f4949  Build Version: 1.6.7594.29634
     For more information, please see http://wiki.ros.org/sw_urdf_exporter -->
<robot
  name="linkerhand_l25_right.urdf">
  <link
    name="hand_base_link">
    <inertial>
      <origin
        xyz="-0.0041187 -0.0001382 0.074952"
        rpy="0 0 0" />
      <mass
        value="0.077055" />
      <inertia
        ixx="0.00019048"
        ixy="-5.5766E-07"
        ixz="7.0822E-06"
        iyy="0.00015943"
        iyz="-4.6343E-06"
        izz="9.8991E-05" />
    </inertial>
    <visual>
      <origin
        xyz="0 0 0"
        rpy="0 0 0" />
      <geometry>
        <mesh
          filename="meshes/hand_base_link.STL" />
      </geometry>
      <material
        name="">
        <color
          rgba="0.82353 0.82353 1 1" />
      </material>
    </visual>
    <collision>
      <origin
        xyz="0 0 0"
        rpy="0 0 0" />
      <geometry>
        <mesh
          filename="meshes/hand_base_link.STL" />
      </geometry>
    </collision>
  </link>
  <link
    name="thumb_metacarpals_base1">
    <inertial>
      <origin
        xyz="0.040785 -0.0022897 -0.0021502"
        rpy="0 0 0" />
      <mass
        value="0.010336" />
      <inertia
        ixx="3.4109E-06"
        ixy="1.7504E-07"
        ixz="-6.9036E-08"
        iyy="2.5673E-06"
        iyz="-8.2693E-08"
        izz="1.8719E-06" />
    </inertial>
    <visual>
      <origin
        xyz="0 0 0"
        rpy="0 0 0" />
      <geometry>
        <mesh
          filename="meshes/thumb_metacarpals_base1.STL" />
      </geometry>
      <material
        name="">
        <color
          rgba="1 1 1 1" />
      </material>
    </visual>
    <collision>
      <origin
        xyz="0 0 0"
        rpy="0 0 0" />
      <geometry>
        <mesh
          filename="meshes/thumb_metacarpals_base1.STL" />
      </geometry>
    </collision>
  </link>
  <joint
    name="thumb_cmc_roll"
    type="revolute">
    <origin
      xyz="-0.016602 0.001612 0.071287"
      rpy="0 0 0" />
    <parent
      link="hand_base_link" />
    <child
      link="thumb_metacarpals_base1" />
    <axis
      xyz="1 0 0" />
    <limit
      lower="-0.46"
      upper="0.61"
      effort="0"
      velocity="0" />
  </joint>
  <link
    name="thumb_metacarpals_base2">
    <inertial>
      <origin
        xyz="0.0001594 0.0009411 -0.00033763"
        rpy="0 0 0" />
      <mass
        value="0.002032" />
      <inertia
        ixx="7.5523E-08"
        ixy="-2.0378E-09"
        ixz="9.7494E-10"
        iyy="7.1811E-08"
        iyz="3.1606E-09"
        izz="1.1702E-07" />
    </inertial>
    <visual>
      <origin
        xyz="0 0 0"
        rpy="0 0 0" />
      <geometry>
        <mesh
          filename="meshes/thumb_metacarpals_base2.STL" />
      </geometry>
      <material
        name="">
        <color
          rgba="0.82353 0.82353 1 1" />
      </material>
    </visual>
    <collision>
      <origin
        xyz="0 0 0"
        rpy="0 0 0" />
      <geometry>
        <mesh
          filename="meshes/thumb_metacarpals_base2.STL" />
      </geometry>
    </collision>
  </link>
  <joint
    name="thumb_cmc_yaw"
    type="revolute">
    <origin
      xyz="0.04625 0.0083829 4.7486E-05"
      rpy="0 0 0" />
    <parent
      link="thumb_metacarpals_base1" />
    <child
      link="thumb_metacarpals_base2" />
    <axis
      xyz="0 0.0056645 -0.99998" />
    <limit
      lower="0"
      upper="1.57"
      effort="0"
      velocity="0" />
  </joint>
  <link
    name="thumb_metacarpals">
    <inertial>
      <origin
        xyz="0.001801 0.016356 -0.0088419"
        rpy="0 0 0" />
      <mass
        value="0.019929" />
      <inertia
        ixx="7.9928E-06"
        ixy="3.4374E-07"
        ixz="1.2988E-08"
        iyy="3.3798E-06"
        iyz="1.5087E-07"
        izz="6.8877E-06" />
    </inertial>
    <visual>
      <origin
        xyz="0 0 0"
        rpy="0 0 0" />
      <geometry>
        <mesh
          filename="meshes/thumb_metacarpals.STL" />
      </geometry>
      <material
        name="">
        <color
          rgba="1 1 1 1" />
      </material>
    </visual>
    <collision>
      <origin
        xyz="0 0 0"
        rpy="0 0 0" />
      <geometry>
        <mesh
          filename="meshes/thumb_metacarpals.STL" />
      </geometry>
    </collision>
  </link>
  <joint
    name="thumb_cmc_pitch"
    type="revolute">
    <origin
      xyz="0.006883 0.014309 0.0015936"
      rpy="0 0 0" />
    <parent
      link="thumb_metacarpals_base2" />
    <child
      link="thumb_metacarpals" />
    <axis
      xyz="1 0 0" />
    <limit
      lower="0"
      upper="1.59"
      effort="0"
      velocity="0" />
  </joint>
  <link
    name="thumb_proximal">
    <inertial>
      <origin
        xyz="-0.0003027 0.025955 -0.0032634"
        rpy="0 0 0" />
      <mass
        value="0.0061014" />
      <inertia
        ixx="2.0127E-06"
        ixy="-2.7504E-08"
        ixz="8.7463E-09"
        iyy="8.2005E-07"
        iyz="9.9171E-08"
        izz="1.8872E-06" />
    </inertial>
    <visual>
      <origin
        xyz="0 0 0"
        rpy="0 0 0" />
      <geometry>
        <mesh
          filename="meshes/thumb_proximal.STL" />
      </geometry>
      <material
        name="">
        <color
          rgba="1 1 1 1" />
      </material>
    </visual>
    <collision>
      <origin
        xyz="0 0 0"
        rpy="0 0 0" />
      <geometry>
        <mesh
          filename="meshes/thumb_proximal.STL" />
      </geometry>
    </collision>
  </link>
  <joint
    name="thumb_mcp"
    type="revolute">
    <origin
      xyz="0 0.034264 -0.0037526"
      rpy="0 0 0" />
    <parent
      link="thumb_metacarpals" />
    <child
      link="thumb_proximal" />
    <axis
      xyz="1 0 0" />
    <limit
      lower="0-"
      upper="1.59"
      effort="0"
      velocity="0" />
  </joint>
  <link
    name="thumb_distal">
    <inertial>
      <origin
        xyz="0.0029999 -2.7882E-08 -2.4065E-09"
        rpy="0 0 0" />
      <mass
        value="4.7112E-06" />
      <inertia
        ixx="5.8883E-13"
        ixy="3.3204E-16"
        ixz="3.2053E-17"
        iyy="1.443E-11"
        iyz="3.2753E-16"
        izz="1.4427E-11" />
    </inertial>
    <visual>
      <origin
        xyz="0 0 0"
        rpy="0 0 0" />
      <geometry>
        <mesh
          filename="meshes/thumb_distal.STL" />
      </geometry>
      <material
        name="">
        <color
          rgba="0.82353 0.82353 1 1" />
      </material>
    </visual>
    <collision>
      <origin
        xyz="0 0 0"
        rpy="0 0 0" />
      <geometry>
        <mesh
          filename="meshes/thumb_distal.STL" />
      </geometry>
    </collision>
  </link>
  <joint
    name="thumb_ip"
    type="revolute">
    <origin
      xyz="0 0.046252 -0.0020512"
      rpy="0 0 0" />
    <parent
      link="thumb_proximal" />
    <child
      link="thumb_distal" />
    <axis
      xyz="1 0 0" />
    <limit
      lower="0"
      upper="1.78"
      effort="0"
      velocity="0" />
  </joint>
  <link
    name="index_metacarpals">
    <inertial>
      <origin
        xyz="-0.001939 -5.7863E-05 0.010294"
        rpy="0 0 0" />
      <mass
        value="0.0029534" />
      <inertia
        ixx="2.0267E-07"
        ixy="-1.2984E-10"
        ixz="2.2411E-08"
        iyy="3.1656E-07"
        iyz="5.7069E-10"
        izz="2.1596E-07" />
    </inertial>
    <visual>
      <origin
        xyz="0 0 0"
        rpy="0 0 0" />
      <geometry>
        <mesh
          filename="meshes/index_metacarpals.STL" />
      </geometry>
      <material
        name="">
        <color
          rgba="1 1 1 1" />
      </material>
    </visual>
    <collision>
      <origin
        xyz="0 0 0"
        rpy="0 0 0" />
      <geometry>
        <mesh
          filename="meshes/index_metacarpals.STL" />
      </geometry>
    </collision>
  </link>
  <joint
    name="index_mcp_roll"
    type="revolute">
    <origin
      xyz="0.0014984 0.032141 0.13508"
      rpy="0 0 0" />
    <parent
      link="hand_base_link" />
    <child
      link="index_metacarpals" />
    <axis
      xyz="1 0 0" />
    <limit
      lower="-0.24"
      upper="0.24"
      effort="0"
      velocity="0" />
  </joint>
  <link
    name="index_proximal">
    <inertial>
      <origin
        xyz="-0.0057676 -0.00013381 0.020157"
        rpy="0 0 0" />
      <mass
        value="0.0093494" />
      <inertia
        ixx="2.4628E-06"
        ixy="-1.1984E-09"
        ixz="6.3455E-08"
        iyy="2.9915E-06"
        iyz="1.4332E-08"
        izz="1.03E-06" />
    </inertial>
    <visual>
      <origin
        xyz="0 0 0"
        rpy="0 0 0" />
      <geometry>
        <mesh
          filename="meshes/index_proximal.STL" />
      </geometry>
      <material
        name="">
        <color
          rgba="1 1 1 1" />
      </material>
    </visual>
    <collision>
      <origin
        xyz="0 0 0"
        rpy="0 0 0" />
      <geometry>
        <mesh
          filename="meshes/index_proximal.STL" />
      </geometry>
    </collision>
  </link>
  <joint
    name="index_mcp_pitch"
    type="revolute">
    <origin
      xyz="0.0068598 -0.00010189 0.018075"
      rpy="0 0 0" />
    <parent
      link="index_metacarpals" />
    <child
      link="index_proximal" />
    <axis
      xyz="0 0.99998 -0.0056645" />
    <limit
      lower="0"
      upper="1.68"
      effort="0"
      velocity="0" />
  </joint>
  <link
    name="index_middle">
    <inertial>
      <origin
        xyz="1.5242E-07 0.0025997 1.4761E-05"
        rpy="0 0 0" />
      <mass
        value="4.0832E-06" />
      <inertia
        ixx="9.4553E-12"
        ixy="-1.8302E-16"
        ixz="1.8964E-16"
        iyy="5.108E-13"
        iyz="-5.0639E-14"
        izz="9.4541E-12" />
    </inertial>
    <visual>
      <origin
        xyz="0 0 0"
        rpy="0 0 0" />
      <geometry>
        <mesh
          filename="meshes/index_middle.STL" />
      </geometry>
      <material
        name="">
        <color
          rgba="1 1 1 1" />
      </material>
    </visual>
    <collision>
      <origin
        xyz="0 0 0"
        rpy="0 0 0" />
      <geometry>
        <mesh
          filename="meshes/index_middle.STL" />
      </geometry>
    </collision>
  </link>
  <joint
    name="index_pip"
    type="revolute">
    <origin
      xyz="-0.0001598 -0.00024924 0.043999"
      rpy="0 0 0" />
    <parent
      link="index_proximal" />
    <child
      link="index_middle" />
    <axis
      xyz="0 0.99998 -0.0056645" />
    <limit
      lower="0"
      upper="1.27"
      effort="0"
      velocity="0" />
  </joint>
  <link
    name="index_distal">
    <inertial>
      <origin
        xyz="-4.8388E-08 0.0027238 1.6151E-07"
        rpy="0 0 0" />
      <mass
        value="9.6249E-06" />
      <inertia
        ixx="2.5159E-11"
        ixy="-8.8856E-16"
        ixz="1.0077E-15"
        iyy="2.7081E-12"
        iyz="3.8719E-15"
        izz="2.5153E-11" />
    </inertial>
    <visual>
      <origin
        xyz="0 0 0"
        rpy="0 0 0" />
      <geometry>
        <mesh
          filename="meshes/index_distal.STL" />
      </geometry>
      <material
        name="">
        <color
          rgba="1 1 1 1" />
      </material>
    </visual>
    <collision>
      <origin
        xyz="0 0 0"
        rpy="0 0 0" />
      <geometry>
        <mesh
          filename="meshes/index_distal.STL" />
      </geometry>
    </collision>
  </link>
  <joint
    name="index_dip"
    type="revolute">
    <origin
      xyz="0.00099206 -0.00025106 0.044322"
      rpy="0 0 0" />
    <parent
      link="index_middle" />
    <child
      link="index_distal" />
    <axis
      xyz="0 1 0" />
    <limit
      lower="0"
      upper="1.78"
      effort="0"
      velocity="0" />
  </joint>
  <link
    name="middle_metacarpals">
    <inertial>
      <origin
        xyz="-0.001939 -5.7863E-05 0.010294"
        rpy="0 0 0" />
      <mass
        value="0.0029534" />
      <inertia
        ixx="2.0267E-07"
        ixy="-1.2984E-10"
        ixz="2.2411E-08"
        iyy="3.1656E-07"
        iyz="5.7069E-10"
        izz="2.1596E-07" />
    </inertial>
    <visual>
      <origin
        xyz="0 0 0"
        rpy="0 0 0" />
      <geometry>
        <mesh
          filename="meshes/middle_metacarpals.STL" />
      </geometry>
      <material
        name="">
        <color
          rgba="1 1 1 1" />
      </material>
    </visual>
    <collision>
      <origin
        xyz="0 0 0"
        rpy="0 0 0" />
      <geometry>
        <mesh
          filename="meshes/middle_metacarpals.STL" />
      </geometry>
    </collision>
  </link>
  <joint
    name="middle_mcp_roll"
    type="revolute">
    <origin
      xyz="0.0014985 0.0099581 0.14231"
      rpy="0 0 0" />
    <parent
      link="hand_base_link" />
    <child
      link="middle_metacarpals" />
    <axis
      xyz="1 0 0" />
    <limit
      lower="-0.24"
      upper="0.24"
      effort="0"
      velocity="0" />
  </joint>
  <link
    name="middle_proximal">
    <inertial>
      <origin
        xyz="-0.0057676 -0.00013381 0.020157"
        rpy="0 0 0" />
      <mass
        value="0.0093494" />
      <inertia
        ixx="2.4628E-06"
        ixy="-1.1984E-09"
        ixz="6.3455E-08"
        iyy="2.9915E-06"
        iyz="1.4332E-08"
        izz="1.03E-06" />
    </inertial>
    <visual>
      <origin
        xyz="0 0 0"
        rpy="0 0 0" />
      <geometry>
        <mesh
          filename="meshes/middle_proximal.STL" />
      </geometry>
      <material
        name="">
        <color
          rgba="1 1 1 1" />
      </material>
    </visual>
    <collision>
      <origin
        xyz="0 0 0"
        rpy="0 0 0" />
      <geometry>
        <mesh
          filename="meshes/middle_proximal.STL" />
      </geometry>
    </collision>
  </link>
  <joint
    name="middle_mcp_pitch"
    type="revolute">
    <origin
      xyz="0.0068598 -0.00010189 0.018075"
      rpy="0 0 0" />
    <parent
      link="middle_metacarpals" />
    <child
      link="middle_proximal" />
    <axis
      xyz="0 0.99998 -0.0056645" />
    <limit
      lower="0"
      upper="1.68"
      effort="0"
      velocity="0" />
  </joint>
  <link
    name="middle_middle">
    <inertial>
      <origin
        xyz="1.5242E-07 0.0025997 1.4761E-05"
        rpy="0 0 0" />
      <mass
        value="4.0832E-06" />
      <inertia
        ixx="9.4553E-12"
        ixy="-1.8302E-16"
        ixz="1.8964E-16"
        iyy="5.108E-13"
        iyz="-5.0639E-14"
        izz="9.4541E-12" />
    </inertial>
    <visual>
      <origin
        xyz="0 0 0"
        rpy="0 0 0" />
      <geometry>
        <mesh
          filename="meshes/middle_middle.STL" />
      </geometry>
      <material
        name="">
        <color
          rgba="1 1 1 1" />
      </material>
    </visual>
    <collision>
      <origin
        xyz="0 0 0"
        rpy="0 0 0" />
      <geometry>
        <mesh
          filename="meshes/middle_middle.STL" />
      </geometry>
    </collision>
  </link>
  <joint
    name="middle_pip"
    type="revolute">
    <origin
      xyz="-0.0001598 -0.00024924 0.043999"
      rpy="0 0 0" />
    <parent
      link="middle_proximal" />
    <child
      link="middle_middle" />
    <axis
      xyz="0 0.99998 -0.0056645" />
    <limit
      lower="0"
      upper="1.27"
      effort="0"
      velocity="0" />
  </joint>
  <link
    name="middle_distal">
    <inertial>
      <origin
        xyz="-4.8388E-08 0.0027238 1.6151E-07"
        rpy="0 0 0" />
      <mass
        value="9.6249E-06" />
      <inertia
        ixx="2.5159E-11"
        ixy="-8.8856E-16"
        ixz="1.0077E-15"
        iyy="2.7081E-12"
        iyz="3.8719E-15"
        izz="2.5153E-11" />
    </inertial>
    <visual>
      <origin
        xyz="0 0 0"
        rpy="0 0 0" />
      <geometry>
        <mesh
          filename="meshes/middle_distal.STL" />
      </geometry>
      <material
        name="">
        <color
          rgba="1 1 1 1" />
      </material>
    </visual>
    <collision>
      <origin
        xyz="0 0 0"
        rpy="0 0 0" />
      <geometry>
        <mesh
          filename="meshes/middle_distal.STL" />
      </geometry>
    </collision>
  </link>
  <joint
    name="middle_dip"
    type="revolute">
    <origin
      xyz="0.00099206 -0.00025106 0.044322"
      rpy="0 0 0" />
    <parent
      link="middle_middle" />
    <child
      link="middle_distal" />
    <axis
      xyz="0 1 0" />
    <limit
      lower="0"
      upper="1.78"
      effort="0"
      velocity="0" />
  </joint>
  <link
    name="ring_metacarpals">
    <inertial>
      <origin
        xyz="-0.001939 -5.7863E-05 0.010294"
        rpy="0 0 0" />
      <mass
        value="0.0029534" />
      <inertia
        ixx="2.0267E-07"
        ixy="-1.2984E-10"
        ixz="2.2411E-08"
        iyy="3.1656E-07"
        iyz="5.7069E-10"
        izz="2.1596E-07" />
    </inertial>
    <visual>
      <origin
        xyz="0 0 0"
        rpy="0 0 0" />
      <geometry>
        <mesh
          filename="meshes/ring_metacarpals.STL" />
      </geometry>
      <material
        name="">
        <color
          rgba="1 1 1 1" />
      </material>
    </visual>
    <collision>
      <origin
        xyz="0 0 0"
        rpy="0 0 0" />
      <geometry>
        <mesh
          filename="meshes/ring_metacarpals.STL" />
      </geometry>
    </collision>
  </link>
  <joint
    name="ring_mcp_roll"
    type="revolute">
    <origin
      xyz="0.0014987 -0.011555 0.13457"
      rpy="0 0 0" />
    <parent
      link="hand_base_link" />
    <child
      link="ring_metacarpals" />
    <axis
      xyz="1 0 0" />
    <limit
      lower="-0.24"
      upper="0.24"
      effort="0"
      velocity="0" />
  </joint>
  <link
    name="ring_proximal">
    <inertial>
      <origin
        xyz="-0.0057676 -0.00013381 0.020157"
        rpy="0 0 0" />
      <mass
        value="0.0093494" />
      <inertia
        ixx="2.4628E-06"
        ixy="-1.1984E-09"
        ixz="6.3455E-08"
        iyy="2.9915E-06"
        iyz="1.4332E-08"
        izz="1.03E-06" />
    </inertial>
    <visual>
      <origin
        xyz="0 0 0"
        rpy="0 0 0" />
      <geometry>
        <mesh
          filename="meshes/ring_proximal.STL" />
      </geometry>
      <material
        name="">
        <color
          rgba="1 1 1 1" />
      </material>
    </visual>
    <collision>
      <origin
        xyz="0 0 0"
        rpy="0 0 0" />
      <geometry>
        <mesh
          filename="meshes/ring_proximal.STL" />
      </geometry>
    </collision>
  </link>
  <joint
    name="ring_mcp_pitch"
    type="revolute">
    <origin
      xyz="0.0068598 -0.00010189 0.018075"
      rpy="0 0 0" />
    <parent
      link="ring_metacarpals" />
    <child
      link="ring_proximal" />
    <axis
      xyz="0 0.99998 -0.0056645" />
    <limit
      lower="0"
      upper="1.68"
      effort="0"
      velocity="0" />
  </joint>
  <link
    name="ring_middle">
    <inertial>
      <origin
        xyz="1.5242E-07 0.0025997 1.4761E-05"
        rpy="0 0 0" />
      <mass
        value="4.0832E-06" />
      <inertia
        ixx="9.4553E-12"
        ixy="-1.8302E-16"
        ixz="1.8964E-16"
        iyy="5.108E-13"
        iyz="-5.0639E-14"
        izz="9.4541E-12" />
    </inertial>
    <visual>
      <origin
        xyz="0 0 0"
        rpy="0 0 0" />
      <geometry>
        <mesh
          filename="meshes/ring_middle.STL" />
      </geometry>
      <material
        name="">
        <color
          rgba="1 1 1 1" />
      </material>
    </visual>
    <collision>
      <origin
        xyz="0 0 0"
        rpy="0 0 0" />
      <geometry>
        <mesh
          filename="meshes/ring_middle.STL" />
      </geometry>
    </collision>
  </link>
  <joint
    name="ring_pip"
    type="revolute">
    <origin
      xyz="-0.0001598 -0.00024924 0.043999"
      rpy="0 0 0" />
    <parent
      link="ring_proximal" />
    <child
      link="ring_middle" />
    <axis
      xyz="0 0.99998 -0.0056645" />
    <limit
      lower="0"
      upper="1.27"
      effort="0"
      velocity="0" />
  </joint>
  <link
    name="ring_distal">
    <inertial>
      <origin
        xyz="-4.8388E-08 0.0027238 1.6151E-07"
        rpy="0 0 0" />
      <mass
        value="9.6249E-06" />
      <inertia
        ixx="2.5159E-11"
        ixy="-8.8856E-16"
        ixz="1.0077E-15"
        iyy="2.7081E-12"
        iyz="3.8719E-15"
        izz="2.5153E-11" />
    </inertial>
    <visual>
      <origin
        xyz="0 0 0"
        rpy="0 0 0" />
      <geometry>
        <mesh
          filename="meshes/ring_distal.STL" />
      </geometry>
      <material
        name="">
        <color
          rgba="1 1 1 1" />
      </material>
    </visual>
    <collision>
      <origin
        xyz="0 0 0"
        rpy="0 0 0" />
      <geometry>
        <mesh
          filename="meshes/ring_distal.STL" />
      </geometry>
    </collision>
  </link>
  <joint
    name="ring_dip"
    type="revolute">
    <origin
      xyz="0.00099206 -0.00025106 0.044322"
      rpy="0 0 0" />
    <parent
      link="ring_middle" />
    <child
      link="ring_distal" />
    <axis
      xyz="0 1 0" />
    <limit
      lower="0"
      upper="1.78"
      effort="0"
      velocity="0" />
  </joint>
  <link
    name="pinky_metacarpals">
    <inertial>
      <origin
        xyz="-0.001939 -5.7863E-05 0.010294"
        rpy="0 0 0" />
      <mass
        value="0.0029534" />
      <inertia
        ixx="2.0267E-07"
        ixy="-1.2984E-10"
        ixz="2.2411E-08"
        iyy="3.1656E-07"
        iyz="5.7069E-10"
        izz="2.1596E-07" />
    </inertial>
    <visual>
      <origin
        xyz="0 0 0"
        rpy="0 0 0" />
      <geometry>
        <mesh
          filename="meshes/pinky_metacarpals.STL" />
      </geometry>
      <material
        name="">
        <color
          rgba="1 1 1 1" />
      </material>
    </visual>
    <collision>
      <origin
        xyz="0 0 0"
        rpy="0 0 0" />
      <geometry>
        <mesh
          filename="meshes/pinky_metacarpals.STL" />
      </geometry>
    </collision>
  </link>
  <joint
    name="pinky_mcp_roll"
    type="revolute">
    <origin
      xyz="0.0014989 -0.033485 0.1194"
      rpy="0 0 0" />
    <parent
      link="hand_base_link" />
    <child
      link="pinky_metacarpals" />
    <axis
      xyz="1 0 0" />
    <limit
      lower="-0.24"
      upper="0.24"
      effort="0"
      velocity="0" />
  </joint>
  <link
    name="pinky_proximal">
    <inertial>
      <origin
        xyz="-0.0057676 -0.00013381 0.020157"
        rpy="0 0 0" />
      <mass
        value="0.0093494" />
      <inertia
        ixx="2.4628E-06"
        ixy="-1.1984E-09"
        ixz="6.3455E-08"
        iyy="2.9915E-06"
        iyz="1.4332E-08"
        izz="1.03E-06" />
    </inertial>
    <visual>
      <origin
        xyz="0 0 0"
        rpy="0 0 0" />
      <geometry>
        <mesh
          filename="meshes/pinky_proximal.STL" />
      </geometry>
      <material
        name="">
        <color
          rgba="1 1 1 1" />
      </material>
    </visual>
    <collision>
      <origin
        xyz="0 0 0"
        rpy="0 0 0" />
      <geometry>
        <mesh
          filename="meshes/pinky_proximal.STL" />
      </geometry>
    </collision>
  </link>
  <joint
    name="pinky_mcp_pitch"
    type="revolute">
    <origin
      xyz="0.0068598 -0.00010189 0.018075"
      rpy="0 0 0" />
    <parent
      link="pinky_metacarpals" />
    <child
      link="pinky_proximal" />
    <axis
      xyz="0 0.99998 -0.0056645" />
    <limit
      lower="0"
      upper="1.68"
      effort="0"
      velocity="0" />
  </joint>
  <link
    name="pinky_middle">
    <inertial>
      <origin
        xyz="1.5242E-07 0.0025997 1.4761E-05"
        rpy="0 0 0" />
      <mass
        value="4.0832E-06" />
      <inertia
        ixx="9.4553E-12"
        ixy="-1.8302E-16"
        ixz="1.8964E-16"
        iyy="5.108E-13"
        iyz="-5.0639E-14"
        izz="9.4541E-12" />
    </inertial>
    <visual>
      <origin
        xyz="0 0 0"
        rpy="0 0 0" />
      <geometry>
        <mesh
          filename="meshes/pinky_middle.STL" />
      </geometry>
      <material
        name="">
        <color
          rgba="1 1 1 1" />
      </material>
    </visual>
    <collision>
      <origin
        xyz="0 0 0"
        rpy="0 0 0" />
      <geometry>
        <mesh
          filename="meshes/pinky_middle.STL" />
      </geometry>
    </collision>
  </link>
  <joint
    name="pinky_pip"
    type="revolute">
    <origin
      xyz="-0.0001598 -0.00024924 0.043999"
      rpy="0 0 0" />
    <parent
      link="pinky_proximal" />
    <child
      link="pinky_middle" />
    <axis
      xyz="0 0.99998 -0.0056645" />
    <limit
      lower="0"
      upper="1.27"
      effort="0"
      velocity="0" />
  </joint>
  <link
    name="pinky_distal">
    <inertial>
      <origin
        xyz="-4.8388E-08 0.0027238 1.6151E-07"
        rpy="0 0 0" />
      <mass
        value="9.6249E-06" />
      <inertia
        ixx="2.5159E-11"
        ixy="-8.8856E-16"
        ixz="1.0077E-15"
        iyy="2.7081E-12"
        iyz="3.8719E-15"
        izz="2.5153E-11" />
    </inertial>
    <visual>
      <origin
        xyz="0 0 0"
        rpy="0 0 0" />
      <geometry>
        <mesh
          filename="meshes/pinky_distal.STL" />
      </geometry>
      <material
        name="">
        <color
          rgba="1 1 1 1" />
      </material>
    </visual>
    <collision>
      <origin
        xyz="0 0 0"
        rpy="0 0 0" />
      <geometry>
        <mesh
          filename="meshes/pinky_distal.STL" />
      </geometry>
    </collision>
  </link>
  <joint
    name="pinky_dip"
    type="revolute">
    <origin
      xyz="0.00099206 -0.00025106 0.044322"
      rpy="0 0 0" />
    <parent
      link="pinky_middle" />
    <child
      link="pinky_distal" />
    <axis
      xyz="0 1 0" />
    <limit
      lower="0"
      upper="1.78"
      effort="0"
      velocity="0" />
  </joint>
</robot>