<?xml version="1.0" encoding="utf-8"?>
<!-- This URDF was automatically created by SolidWorks to URDF Exporter! Originally created by Stephen Brawner (brawner@gmail.com) 
     Commit Version: 1.6.0-1-g15f4949  Build Version: 1.6.7594.29634
     For more information, please see http://wiki.ros.org/sw_urdf_exporter -->
<robot
  name="linkerhand_l20pro_v1.0_right.urdf">
  <link
    name="base_link">
    <inertial>
      <origin
        xyz="-0.00631544454449476 0.0016887294851371 0.206318093383433"
        rpy="0 0 0" />
      <mass
        value="0.0184557796122669" />
      <inertia
        ixx="9.4731935680696E-05"
        ixy="5.28483125141477E-07"
        ixz="-1.71603786808366E-05"
        iyy="8.67320870706719E-05"
        iyz="-4.689501036235E-06"
        izz="1.58260679860554E-05" />
    </inertial>
    <visual>
      <origin
        xyz="0 0 0"
        rpy="0 0 0" />
      <geometry>
        <mesh
          filename="meshes/base_link.STL" />
      </geometry>
      <material
        name="">
        <color
          rgba="1 1 1 1" />
      </material>
    </visual>
    <collision>
      <origin
        xyz="0 0 0"
        rpy="0 0 0" />
      <geometry>
        <mesh
          filename="meshes/base_link.STL" />
      </geometry>
    </collision>
  </link>
  <link
    name="index_metacarpals">
    <inertial>
      <origin
        xyz="-0.00381524728449285 -0.0335612705443158 0.0588181054434941"
        rpy="0 0 0" />
      <mass
        value="0.0184557796122669" />
      <inertia
        ixx="9.47319356759753E-05"
        ixy="5.28483149494152E-07"
        ixz="-1.71603786976198E-05"
        iyy="8.67320870719603E-05"
        iyz="-4.68950100205031E-06"
        izz="1.58260679894876E-05" />
    </inertial>
    <visual>
      <origin
        xyz="0 0 0"
        rpy="0 0 0" />
      <geometry>
        <mesh
          filename="meshes/index_metacarpals.STL" />
      </geometry>
      <material
        name="">
        <color
          rgba="1 1 1 1" />
      </material>
    </visual>
    <collision>
      <origin
        xyz="0 0 0"
        rpy="0 0 0" />
      <geometry>
        <mesh
          filename="meshes/index_metacarpals.STL" />
      </geometry>
    </collision>
  </link>
  <joint
    name="index_mcp_roll"
    type="revolute">
    <origin
      xyz="-0.00250019735262905 0.0352500000300422 0.147499987934267"
      rpy="0 0 0" />
    <parent
      link="base_link" />
    <child
      link="index_metacarpals" />
    <axis
      xyz="1 0 0" />
    <limit
      lower="-0.2618"
      upper="0.2618"
      effort="100"
      velocity="1" />
  </joint>
  <link
    name="index_proximal">
    <inertial>
      <origin
        xyz="-0.00381524728449285 -0.0335612705443158 0.0588181054434941"
        rpy="0 0 0" />
      <mass
        value="0.0184557796122669" />
      <inertia
        ixx="9.47319356759753E-05"
        ixy="5.28483149494152E-07"
        ixz="-1.71603786976198E-05"
        iyy="8.67320870719603E-05"
        iyz="-4.68950100205031E-06"
        izz="1.58260679894876E-05" />
    </inertial>
    <visual>
      <origin
        xyz="0 0 0"
        rpy="0 0 0" />
      <geometry>
        <mesh
          filename="meshes/index_proximal.STL" />
      </geometry>
      <material
        name="">
        <color
          rgba="1 1 1 1" />
      </material>
    </visual>
    <collision>
      <origin
        xyz="0 0 0"
        rpy="0 0 0" />
      <geometry>
        <mesh
          filename="meshes/index_proximal.STL" />
      </geometry>
    </collision>
  </link>
  <joint
    name="index_mcp_pitch"
    type="revolute">
    <origin
      xyz="0 0 0"
      rpy="0 0 0" />
    <parent
      link="index_metacarpals" />
    <child
      link="index_proximal" />
    <axis
      xyz="0 1 0" />
    <limit
      lower="0"
      upper="1.3422"
      effort="100"
      velocity="1" />
  </joint>
  <link
    name="index_middle">
    <inertial>
      <origin
        xyz="0.000379310015347818 -0.0335612705427152 0.0139986727610816"
        rpy="0 0 0" />
      <mass
        value="0.0184557796122669" />
      <inertia
        ixx="9.47318862679643E-05"
        ixy="5.28489900856422E-07"
        ixz="-1.71604922899797E-05"
        iyy="8.67320870723408E-05"
        iyz="-4.68950023734492E-06"
        izz="1.58261173971183E-05" />
    </inertial>
    <visual>
      <origin
        xyz="0 0 0"
        rpy="0 0 0" />
      <geometry>
        <mesh
          filename="meshes/index_middle.STL" />
      </geometry>
      <material
        name="">
        <color
          rgba="1 1 1 1" />
      </material>
    </visual>
    <collision>
      <origin
        xyz="0 0 0"
        rpy="0 0 0" />
      <geometry>
        <mesh
          filename="meshes/index_middle.STL" />
      </geometry>
    </collision>
  </link>
  <joint
    name="index_pip"
    type="revolute">
    <origin
      xyz="-0.00419457745591119 0 0.0448194332294146"
      rpy="0 0 0" />
    <parent
      link="index_proximal" />
    <child
      link="index_middle" />
    <axis
      xyz="0 1 0" />
    <limit
      lower="0"
      upper="1.69297"
      effort="100"
      velocity="1" />
  </joint>
  <link
    name="index_distal">
    <inertial>
      <origin
        xyz="-0.00852377306534634 -0.000203307583503763 0.00894633822362381"
        rpy="0 0 0" />
      <mass
        value="0.00818272691763665" />
      <inertia
        ixx="4.17703277687667E-07"
        ixy="-1.76519629509578E-10"
        ixz="-1.38305988666323E-07"
        iyy="4.49663376327698E-07"
        iyz="8.78549591407587E-11"
        izz="3.19809016538874E-07" />
    </inertial>
    <visual>
      <origin
        xyz="0 0 0"
        rpy="0 0 0" />
      <geometry>
        <mesh
          filename="meshes/index_distal.STL" />
      </geometry>
      <material
        name="">
        <color
          rgba="0.866666666666667 0.866666666666667 0.890196078431372 1" />
      </material>
    </visual>
    <collision>
      <origin
        xyz="0 0 0"
        rpy="0 0 0" />
      <geometry>
        <mesh
          filename="meshes/index_distal.STL" />
      </geometry>
    </collision>
  </link>
  <joint
    name="index_dip"
    type="revolute">
    <origin
      xyz="0.00320206348796069 0 0.0316604484170347"
      rpy="0 0 0" />
    <parent
      link="index_middle" />
    <child
      link="index_distal" />
    <axis
      xyz="0 1 0" />
    <limit
      lower="0"
      upper="1.25"
      effort="100"
      velocity="1" />
    <mimic
      joint="index_pip"
      multiplier="0.7396"
      offset="0" />
  </joint>
  <link
    name="middle_metacarpals">
    <inertial>
      <origin
        xyz="-0.00131524716759281 -0.0100612705239658 0.0543181054400746"
        rpy="0 0 0" />
      <mass
        value="0.0184557796122669" />
      <inertia
        ixx="9.473193568938E-05"
        ixy="5.28483125398019E-07"
        ixz="-1.71603786608279E-05"
        iyy="8.67320870698851E-05"
        iyz="-4.68950104231411E-06"
        izz="1.58260679781582E-05" />
    </inertial>
    <visual>
      <origin
        xyz="0 0 0"
        rpy="0 0 0" />
      <geometry>
        <mesh
          filename="meshes/middle_metacarpals.STL" />
      </geometry>
      <material
        name="">
        <color
          rgba="1 1 1 1" />
      </material>
    </visual>
    <collision>
      <origin
        xyz="0 0 0"
        rpy="0 0 0" />
      <geometry>
        <mesh
          filename="meshes/middle_metacarpals.STL" />
      </geometry>
    </collision>
  </link>
  <joint
    name="middle_mcp_roll"
    type="revolute">
    <origin
      xyz="-0.0050002 0.01175 0.152"
      rpy="0 0 0" />
    <parent
      link="base_link" />
    <child
      link="middle_metacarpals" />
    <axis
      xyz="1 0 0" />
    <limit
      lower="-0.2618"
      upper="0.2618"
      effort="100"
      velocity="1" />
  </joint>
  <link
    name="middle_proximal">
    <inertial>
      <origin
        xyz="-0.00131524716759281 -0.0100612705239658 0.0543181054400746"
        rpy="0 0 0" />
      <mass
        value="0.0184557796122669" />
      <inertia
        ixx="9.473193568938E-05"
        ixy="5.28483125398019E-07"
        ixz="-1.71603786608279E-05"
        iyy="8.67320870698851E-05"
        iyz="-4.68950104231411E-06"
        izz="1.58260679781582E-05" />
    </inertial>
    <visual>
      <origin
        xyz="0 0 0"
        rpy="0 0 0" />
      <geometry>
        <mesh
          filename="meshes/middle_proximal.STL" />
      </geometry>
      <material
        name="">
        <color
          rgba="1 1 1 1" />
      </material>
    </visual>
    <collision>
      <origin
        xyz="0 0 0"
        rpy="0 0 0" />
      <geometry>
        <mesh
          filename="meshes/middle_proximal.STL" />
      </geometry>
    </collision>
  </link>
  <joint
    name="middle_mcp_pitch"
    type="revolute">
    <origin
      xyz="0 0 0"
      rpy="0 0 0" />
    <parent
      link="middle_metacarpals" />
    <child
      link="middle_proximal" />
    <axis
      xyz="0 1 0" />
    <limit
      lower="0"
      upper="1.3422"
      effort="100"
      velocity="1" />
  </joint>
  <link
    name="middle_middle">
    <inertial>
      <origin
        xyz="0.0028793 -0.010061 0.0094987"
        rpy="0 0 0" />
      <mass
        value="0.018456" />
      <inertia
        ixx="9.4732E-05"
        ixy="5.2849E-07"
        ixz="-1.716E-05"
        iyy="8.6732E-05"
        iyz="-4.6895E-06"
        izz="1.5826E-05" />
    </inertial>
    <visual>
      <origin
        xyz="0 0 0"
        rpy="0 0 0" />
      <geometry>
        <mesh
          filename="meshes/middle_middle.STL" />
      </geometry>
      <material
        name="">
        <color
          rgba="1 1 1 1" />
      </material>
    </visual>
    <collision>
      <origin
        xyz="0 0 0"
        rpy="0 0 0" />
      <geometry>
        <mesh
          filename="meshes/middle_middle.STL" />
      </geometry>
    </collision>
  </link>
  <joint
    name="middle_pip"
    type="revolute">
    <origin
      xyz="-0.00419457745591117 0 0.0448194332294145"
      rpy="0 0 0" />
    <parent
      link="middle_proximal" />
    <child
      link="middle_middle" />
    <axis
      xyz="0 1 0" />
    <limit
      lower="0"
      upper="1.69297"
      effort="100"
      velocity="1" />
  </joint>
  <link
    name="middle_distal">
    <inertial>
      <origin
        xyz="-0.00845381260393399 -0.000203304591779665 0.00901246396592514"
        rpy="0 0 0" />
      <mass
        value="0.00818272151090883" />
      <inertia
        ixx="4.19852064101858E-07"
        ixy="-1.75674500068995E-10"
        ixz="-1.37526252586203E-07"
        iyy="4.49662692918361E-07"
        iyz="8.91184159243184E-11"
        izz="3.17660052164253E-07" />
    </inertial>
    <visual>
      <origin
        xyz="0 0 0"
        rpy="0 0 0" />
      <geometry>
        <mesh
          filename="meshes/middle_distal.STL" />
      </geometry>
      <material
        name="">
        <color
          rgba="0.866666666666667 0.866666666666667 0.890196078431372 1" />
      </material>
    </visual>
    <collision>
      <origin
        xyz="0 0 0"
        rpy="0 0 0" />
      <geometry>
        <mesh
          filename="meshes/middle_distal.STL" />
      </geometry>
    </collision>
  </link>
  <joint
    name="middle_dip"
    type="revolute">
    <origin
      xyz="0.0032021 0 0.03166"
      rpy="0 0 0" />
    <parent
      link="middle_middle" />
    <child
      link="middle_distal" />
    <axis
      xyz="0 1 0" />
    <limit
      lower="0"
      upper="1.25"
      effort="100"
      velocity="1" />
    <mimic
      joint="middle_pip"
      multiplier="0.7396"
      offset="0" />
  </joint>
  <link
    name="ring_metacarpals">
    <inertial>
      <origin
        xyz="-0.00381524716644589 0.0134387294756574 0.0588181054426797"
        rpy="0 0 0" />
      <mass
        value="0.0184557796122669" />
      <inertia
        ixx="9.473193568938E-05"
        ixy="5.28483125397999E-07"
        ixz="-1.71603786608279E-05"
        iyy="8.67320870698851E-05"
        iyz="-4.68950104231402E-06"
        izz="1.58260679781582E-05" />
    </inertial>
    <visual>
      <origin
        xyz="0 0 0"
        rpy="0 0 0" />
      <geometry>
        <mesh
          filename="meshes/ring_metacarpals.STL" />
      </geometry>
      <material
        name="">
        <color
          rgba="1 1 1 1" />
      </material>
    </visual>
    <collision>
      <origin
        xyz="0 0 0"
        rpy="0 0 0" />
      <geometry>
        <mesh
          filename="meshes/ring_metacarpals.STL" />
      </geometry>
    </collision>
  </link>
  <joint
    name="ring_mcp_roll"
    type="revolute">
    <origin
      xyz="-0.00250019736316104 -0.0117499999954557 0.147499987942847"
      rpy="0 0 0" />
    <parent
      link="base_link" />
    <child
      link="ring_metacarpals" />
    <axis
      xyz="1 0 0" />
    <limit
      lower="-0.2618"
      upper="0.2618"
      effort="100"
      velocity="1" />
  </joint>
  <link
    name="ring_proximal">
    <inertial>
      <origin
        xyz="-0.00381524716644589 0.0134387294756574 0.0588181054426797"
        rpy="0 0 0" />
      <mass
        value="0.0184557796122669" />
      <inertia
        ixx="9.473193568938E-05"
        ixy="5.28483125397999E-07"
        ixz="-1.71603786608279E-05"
        iyy="8.67320870698851E-05"
        iyz="-4.68950104231403E-06"
        izz="1.58260679781582E-05" />
    </inertial>
    <visual>
      <origin
        xyz="0 0 0"
        rpy="0 0 0" />
      <geometry>
        <mesh
          filename="meshes/ring_proximal.STL" />
      </geometry>
      <material
        name="">
        <color
          rgba="1 1 1 1" />
      </material>
    </visual>
    <collision>
      <origin
        xyz="0 0 0"
        rpy="0 0 0" />
      <geometry>
        <mesh
          filename="meshes/ring_proximal.STL" />
      </geometry>
    </collision>
  </link>
  <joint
    name="ring_mcp_pitch"
    type="revolute">
    <origin
      xyz="0 0 0"
      rpy="0 0 0" />
    <parent
      link="ring_metacarpals" />
    <child
      link="ring_proximal" />
    <axis
      xyz="0 1 0" />
    <limit
      lower="0"
      upper="1.3422"
      effort="100"
      velocity="1" />
  </joint>
  <link
    name="ring_middle">
    <inertial>
      <origin
        xyz="0.00037931 0.013439 0.013999"
        rpy="0 0 0" />
      <mass
        value="0.018456" />
      <inertia
        ixx="9.4732E-05"
        ixy="5.2849E-07"
        ixz="-1.716E-05"
        iyy="8.6732E-05"
        iyz="-4.6895E-06"
        izz="1.5826E-05" />
    </inertial>
    <visual>
      <origin
        xyz="0 0 0"
        rpy="0 0 0" />
      <geometry>
        <mesh
          filename="meshes/ring_middle.STL" />
      </geometry>
      <material
        name="">
        <color
          rgba="1 1 1 1" />
      </material>
    </visual>
    <collision>
      <origin
        xyz="0 0 0"
        rpy="0 0 0" />
      <geometry>
        <mesh
          filename="meshes/ring_middle.STL" />
      </geometry>
    </collision>
  </link>
  <joint
    name="ring_pip"
    type="revolute">
    <origin
      xyz="-0.00419457745591118 0 0.0448194332294145"
      rpy="0 0 0" />
    <parent
      link="ring_proximal" />
    <child
      link="ring_middle" />
    <axis
      xyz="0 1 0" />
    <limit
      lower="0"
      upper="1.69297"
      effort="100"
      velocity="1" />
  </joint>
  <link
    name="ring_distal">
    <inertial>
      <origin
        xyz="-0.00845547664679549 0.000195533577426556 0.00901097120211655"
        rpy="0 0 0" />
      <mass
        value="0.00818275453986967" />
      <inertia
        ixx="4.19803325595036E-07"
        ixy="-1.75687640844023E-10"
        ixz="-1.37546551087708E-07"
        iyy="4.49666480008407E-07"
        iyz="8.91125389758761E-11"
        izz="3.1771264359821E-07" />
    </inertial>
    <visual>
      <origin
        xyz="0 0 0"
        rpy="0 0 0" />
      <geometry>
        <mesh
          filename="meshes/ring_distal.STL" />
      </geometry>
      <material
        name="">
        <color
          rgba="0.866666666666667 0.866666666666667 0.890196078431372 1" />
      </material>
    </visual>
    <collision>
      <origin
        xyz="0 0 0"
        rpy="0 0 0" />
      <geometry>
        <mesh
          filename="meshes/ring_distal.STL" />
      </geometry>
    </collision>
  </link>
  <joint
    name="ring_dip"
    type="revolute">
    <origin
      xyz="0.00320206348796068 0 0.0316604484170347"
      rpy="0 0 0" />
    <parent
      link="ring_middle" />
    <child
      link="ring_distal" />
    <axis
      xyz="0 1 0" />
    <limit
      lower="0"
      upper="1.25"
      effort="100"
      velocity="1" />
    <mimic
      joint="ring_pip"
      multiplier="0.7396"
      offset="0" />
  </joint>
  <link
    name="pinky_metacarpals">
    <inertial>
      <origin
        xyz="-0.00731533831723678 0.03693872947705 0.0633180949135027"
        rpy="0 0 0" />
      <mass
        value="0.0184557796122669" />
      <inertia
        ixx="9.47318862814874E-05"
        ixy="5.28489875864518E-07"
        ixz="-1.71604922526628E-05"
        iyy="8.67320870701472E-05"
        iyz="-4.68950027953051E-06"
        izz="1.58261173857887E-05" />
    </inertial>
    <visual>
      <origin
        xyz="0 0 0"
        rpy="0 0 0" />
      <geometry>
        <mesh
          filename="meshes/pinky_metacarpals.STL" />
      </geometry>
      <material
        name="">
        <color
          rgba="1 1 1 1" />
      </material>
    </visual>
    <collision>
      <origin
        xyz="0 0 0"
        rpy="0 0 0" />
      <geometry>
        <mesh
          filename="meshes/pinky_metacarpals.STL" />
      </geometry>
    </collision>
  </link>
  <joint
    name="pinky_mcp_roll"
    type="revolute">
    <origin
      xyz="0.0009998 -0.03525 0.143"
      rpy="0 0 0" />
    <parent
      link="base_link" />
    <child
      link="pinky_metacarpals" />
    <axis
      xyz="1 0 0" />
    <limit
      lower="-0.2618"
      upper="0.2618"
      effort="100"
      velocity="1" />
  </joint>
  <link
    name="pinky_proximal">
    <inertial>
      <origin
        xyz="-0.00731533831723678 0.03693872947705 0.0633180949135027"
        rpy="0 0 0" />
      <mass
        value="0.0184557796122669" />
      <inertia
        ixx="9.47318862814874E-05"
        ixy="5.28489875864518E-07"
        ixz="-1.71604922526628E-05"
        iyy="8.67320870701472E-05"
        iyz="-4.68950027953051E-06"
        izz="1.58261173857887E-05" />
    </inertial>
    <visual>
      <origin
        xyz="0 0 0"
        rpy="0 0 0" />
      <geometry>
        <mesh
          filename="meshes/pinky_proximal.STL" />
      </geometry>
      <material
        name="">
        <color
          rgba="1 1 1 1" />
      </material>
    </visual>
    <collision>
      <origin
        xyz="0 0 0"
        rpy="0 0 0" />
      <geometry>
        <mesh
          filename="meshes/pinky_proximal.STL" />
      </geometry>
    </collision>
  </link>
  <joint
    name="pinky_mcp_pitch"
    type="revolute">
    <origin
      xyz="0 0 0"
      rpy="0 0 0" />
    <parent
      link="pinky_metacarpals" />
    <child
      link="pinky_proximal" />
    <axis
      xyz="0 1 0" />
    <limit
      lower="0"
      upper="1.3422"
      effort="100"
      velocity="1" />
  </joint>
  <link
    name="pinky_middle">
    <inertial>
      <origin
        xyz="0.00037931 0.013439 0.013999"
        rpy="0 0 0" />
      <mass
        value="0.018456" />
      <inertia
        ixx="9.4732E-05"
        ixy="5.2849E-07"
        ixz="-1.716E-05"
        iyy="8.6732E-05"
        iyz="-4.6895E-06"
        izz="1.5826E-05" />
    </inertial>
    <visual>
      <origin
        xyz="0 0 0"
        rpy="0 0 0" />
      <geometry>
        <mesh
          filename="meshes/pinky_middle.STL" />
      </geometry>
      <material
        name="">
        <color
          rgba="1 1 1 1" />
      </material>
    </visual>
    <collision>
      <origin
        xyz="0 0 0"
        rpy="0 0 0" />
      <geometry>
        <mesh
          filename="meshes/pinky_middle.STL" />
      </geometry>
    </collision>
  </link>
  <joint
    name="pinky_pip"
    type="revolute">
    <origin
      xyz="-0.0076946 0.0235 0.049319"
      rpy="0 0 0" />
    <parent
      link="pinky_proximal" />
    <child
      link="pinky_middle" />
    <axis
      xyz="0 1 0" />
    <limit
      lower="0"
      upper="1.693"
      effort="100"
      velocity="1" />
  </joint>
  <link
    name="pinky_distal">
    <inertial>
      <origin
        xyz="-0.00850222473325968 -0.000203303795147866 0.00896687092586304"
        rpy="0 0 0" />
      <mass
        value="0.00818275926134031" />
      <inertia
        ixx="4.18369702106363E-07"
        ixy="-1.76118934274718E-10"
        ixz="-1.38070197893498E-07"
        iyy="4.49666801705453E-07"
        iyz="8.82034372859545E-11"
        izz="3.19146202279066E-07" />
    </inertial>
    <visual>
      <origin
        xyz="0 0 0"
        rpy="0 0 0" />
      <geometry>
        <mesh
          filename="meshes/pinky_distal.STL" />
      </geometry>
      <material
        name="">
        <color
          rgba="0.866666666666667 0.866666666666667 0.890196078431372 1" />
      </material>
    </visual>
    <collision>
      <origin
        xyz="0 0 0"
        rpy="0 0 0" />
      <geometry>
        <mesh
          filename="meshes/pinky_distal.STL" />
      </geometry>
    </collision>
  </link>
  <joint
    name="pinky_dip"
    type="revolute">
    <origin
      xyz="0.00670206996232169 -0.0235000000005 0.0271604534533937"
      rpy="0 0 0" />
    <parent
      link="pinky_middle" />
    <child
      link="pinky_distal" />
    <axis
      xyz="0 1 0" />
    <limit
      lower="0"
      upper="1.24"
      effort="100"
      velocity="1" />
    <mimic
      joint="pinky_pip"
      multiplier="0.7396"
      offset="0" />
  </joint>
  <link
    name="thumb_metacarpals_base1">
    <inertial>
      <origin
        xyz="0.0134724353960023 1.0351626304559E-05 -0.00238205216079675"
        rpy="0 0 0" />
      <mass
        value="0.00252176316153845" />
      <inertia
        ixx="6.26810855308573E-07"
        ixy="-3.32426835069964E-09"
        ixz="1.29826443185812E-08"
        iyy="3.58172006507018E-07"
        iyz="-3.52633067696522E-10"
        izz="2.94683211652898E-07" />
    </inertial>
    <visual>
      <origin
        xyz="0 0 0"
        rpy="0 0 0" />
      <geometry>
        <mesh
          filename="meshes/thumb_metacarpals_base1.STL" />
      </geometry>
      <material
        name="">
        <color
          rgba="1 1 1 1" />
      </material>
    </visual>
    <collision>
      <origin
        xyz="0 0 0"
        rpy="0 0 0" />
      <geometry>
        <mesh
          filename="meshes/thumb_metacarpals_base1.STL" />
      </geometry>
    </collision>
  </link>
  <joint
    name="thumb_cmc_roll"
    type="revolute">
    <origin
      xyz="0.0148 0.013 0.0415000000000001"
      rpy="0 0 0" />
    <parent
      link="base_link" />
    <child
      link="thumb_metacarpals_base1" />
    <axis
      xyz="1 0 0" />
    <limit
      lower="-0.31416"
      upper="0.61087"
      effort="100"
      velocity="1" />
  </joint>
  <link
    name="thumb_metacarpals_base2">
    <inertial>
      <origin
        xyz="-0.041115 -0.011311 0.16482"
        rpy="0 0 0" />
      <mass
        value="0.018456" />
      <inertia
        ixx="9.4732E-05"
        ixy="5.2848E-07"
        ixz="-1.716E-05"
        iyy="8.6732E-05"
        iyz="-4.6895E-06"
        izz="1.5826E-05" />
    </inertial>
    <visual>
      <origin
        xyz="0 0 0"
        rpy="0 0 0" />
      <geometry>
        <mesh
          filename="meshes/thumb_metacarpals_base2.STL" />
      </geometry>
      <material
        name="">
        <color
          rgba="1 1 1 1" />
      </material>
    </visual>
    <collision>
      <origin
        xyz="0 0 0"
        rpy="0 0 0" />
      <geometry>
        <mesh
          filename="meshes/thumb_metacarpals_base2.STL" />
      </geometry>
    </collision>
  </link>
  <joint
    name="thumb_cmc_yaw"
    type="revolute">
    <origin
      xyz="0.02 0 0"
      rpy="0 0 0" />
    <parent
      link="thumb_metacarpals_base1" />
    <child
      link="thumb_metacarpals_base2" />
    <axis
      xyz="0 0 -1" />
    <limit
      lower="0"
      upper="1.75"
      effort="100"
      velocity="1" />
  </joint>
  <link
    name="thumb_metacarpals">
    <inertial>
      <origin
        xyz="-0.0347244266453636 -0.0435515416671891 0.164318093383433"
        rpy="0 0 0" />
      <mass
        value="0.0184557796122669" />
      <inertia
        ixx="9.41283174799894E-05"
        ixy="-2.17802518471267E-06"
        ixz="-1.45037772923998E-05"
        iyy="8.73357052713785E-05"
        iyz="-1.03009931895439E-05"
        izz="1.58260679860554E-05" />
    </inertial>
    <visual>
      <origin
        xyz="0 0 0"
        rpy="0 0 0" />
      <geometry>
        <mesh
          filename="meshes/thumb_metacarpals.STL" />
      </geometry>
      <material
        name="">
        <color
          rgba="1 1 1 1" />
      </material>
    </visual>
    <collision>
      <origin
        xyz="0 0 0"
        rpy="0 0 0" />
      <geometry>
        <mesh
          filename="meshes/thumb_metacarpals.STL" />
      </geometry>
    </collision>
  </link>
  <joint
    name="thumb_cmc_pitch"
    type="revolute">
    <origin
      xyz="0.00646053351359761 0.0176550702836233 0.000499999999999952"
      rpy="0 0 -0.350795957657626" />
    <parent
      link="thumb_metacarpals_base2" />
    <child
      link="thumb_metacarpals" />
    <axis
      xyz="1 0 0" />
    <limit
      lower="0"
      upper="0.73304"
      effort="100"
      velocity="1" />
  </joint>
  <link
    name="thumb_proximal">
    <inertial>
      <origin
        xyz="0.151436626625708 -0.034724426647133 -0.0125219214388285"
        rpy="0 0 0" />
      <mass
        value="0.0184557796122669" />
      <inertia
        ixx="3.32279829057112E-05"
        ixy="-1.00399637165933E-05"
        ixz="3.23680157222152E-05"
        iyy="9.41283174799731E-05"
        iyz="-1.06912336998037E-05"
        izz="6.99337903517389E-05" />
    </inertial>
    <visual>
      <origin
        xyz="0 0 0"
        rpy="0 0 0" />
      <geometry>
        <mesh
          filename="meshes/thumb_proximal.STL" />
      </geometry>
      <material
        name="">
        <color
          rgba="1 1 1 1" />
      </material>
    </visual>
    <collision>
      <origin
        xyz="0 0 0"
        rpy="0 0 0" />
      <geometry>
        <mesh
          filename="meshes/thumb_proximal.STL" />
      </geometry>
    </collision>
  </link>
  <joint
    name="thumb_mcp"
    type="revolute">
    <origin
      xyz="0 0.0600532698441728 0.0531610268874242"
      rpy="0 -0.903049247099703 -1.57079632679359" />
    <parent
      link="thumb_metacarpals" />
    <child
      link="thumb_proximal" />
    <axis
      xyz="0 1 0" />
    <limit
      lower="0"
      upper="0.83776"
      effort="100"
      velocity="1" />
  </joint>
  <link
    name="thumb_distal">
    <inertial>
      <origin
        xyz="0.153583725298444 -0.0347244266470092 -0.0470514445684649"
        rpy="0 0 0" />
      <mass
        value="0.0184557796122669" />
      <inertia
        ixx="3.3227982905695E-05"
        ixy="-1.00399637165439E-05"
        ixz="3.23680157222239E-05"
        iyy="9.41283174799894E-05"
        iyz="-1.06912336997775E-05"
        izz="6.9933790351739E-05" />
    </inertial>
    <visual>
      <origin
        xyz="0 0 0"
        rpy="0 0 0" />
      <geometry>
        <mesh
          filename="meshes/thumb_distal.STL" />
      </geometry>
      <material
        name="">
        <color
          rgba="1 1 1 1" />
      </material>
    </visual>
    <collision>
      <origin
        xyz="0 0 0"
        rpy="0 0 0" />
      <geometry>
        <mesh
          filename="meshes/thumb_distal.STL" />
      </geometry>
    </collision>
  </link>
  <joint
    name="thumb_ip"
    type="revolute">
    <origin
      xyz="-0.0021470986727075 0 0.0345295231296363"
      rpy="0 0 0" />
    <parent
      link="thumb_proximal" />
    <child
      link="thumb_distal" />
    <axis
      xyz="0 1 0" />
    <limit
      lower="0"
      upper="1.39626"
      effort="100"
      velocity="1" />
  </joint>
</robot>